Workbook

Sheet bono 10a esp
E5: HORIZONTE DE INVERSIÓN
D6: 1+r medio | E6: 1 | F6: =+E6+1 -> 2 | G6: =+F6+1 -> 3 | H6: =+G6+1 -> 4 | I6: =+H6+1 -> 5 | J6: =+I6+1 -> 6 | K6: =+J6+1 -> 7 | L6: =+K6+1 -> 8 | M6: =+L6+1 -> 9 | ... Z6: =+Y6+1 -> 22
A7: 1999 | B7: 0.0485 | D7: =1+B7 -> 1.0485 | E7: =+D7-1 -> 0.0485 | F7: =+IF(TYPE(GEOMEAN($D7:$D8)-1)>1,"",GEOMEAN($D7:$D8)-1) -> 0.053388604 | G7: =+IF(TYPE(GEOMEAN($D7:$D9)-1)>1,"",GEOMEAN($D7:$D9)-1) -> 0.052992253 | H7: =+IF(TYPE(GEOMEAN($D7:$D10)-1)>1,"",GEOMEAN($D7:$D10)-1) -> 0.052694063 | I7: =+IF(TYPE(GEOMEAN($D7:$D11)-1)>1,"",GEOMEAN($D7:$D11)-1) -> 0.050808508 | J7: =+IF(TYPE(GEOMEAN($D7:$D12)-1)>1,"",GEOMEAN($D7:$D12)-1) -> 0.049503042 | K7: =+IF(TYPE(GEOMEAN($D7:$D13)-1)>1,"",GEOMEAN($D7:$D13)-1) -> 0.047967311 | L7: =+IF(TYPE(GEOMEAN($D7:$D14)-1)>1,"",GEOMEAN($D7:$D14)-1) -> 0.046122571 | M7: =+IF(TYPE(GEOMEAN($D7:$D15)-1)>1,"",GEOMEAN($D7:$D15)-1) -> 0.04544051 | N7: =+IF(TYPE(GEOMEAN($D7:$D16)-1)>1,"",GEOMEAN($D7:$D16)-1) -> 0.045296369 | O7: =+IF(TYPE(GEOMEAN($D7:$D17)-1)>1,"",GEOMEAN($D7:$D17)-1) -> 0.04477723 | P7: =+IF(TYPE(GEOMEAN($D7:$D18)-1)>1,"",GEOMEAN($D7:$D18)-1) -> 0.04429457 | Q7: =+IF(TYPE(GEOMEAN($D7:$D19)-1)>1,"",GEOMEAN($D7:$D19)-1) -> 0.045076084 | R7: =+IF(TYPE(GEOMEAN($D7:$D20)-1)>1,"",GEOMEAN($D7:$D20)-1) -> 0.045441248 | S7: =+IF(TYPE(GEOMEAN($D7:$D21)-1)>1,"",GEOMEAN($D7:$D21)-1) -> 0.046115446 | T7: =+IF(TYPE(GEOMEAN($D7:$D22)-1)>1,"",GEOMEAN($D7:$D22)-1) -> 0.045813829 | U7: =+IF(TYPE(GEOMEAN($D7:$D23)-1)>1,"",GEOMEAN($D7:$D23)-1) -> 0.044048192 | V7: =+IF(TYPE(GEOMEAN($D7:$D24)-1)>1,"",GEOMEAN($D7:$D24)-1) -> 0.04257236 | W7: =+IF(TYPE(GEOMEAN($D7:$D25)-1)>1,"",GEOMEAN($D7:$D25)-1) -> 0.041027057 | X7: =+IF(TYPE(GEOMEAN($D7:$D26)-1)>1,"",GEOMEAN($D7:$D26)-1) -> 0.039592067 | Y7: =+IF(TYPE(GEOMEAN($D7:$D27)-1)>1,"",GEOMEAN($D7:$D27)-1) -> 0.037840926 | Z7: =+IF(TYPE(GEOMEAN($D7:$D28)-1)>1,"",GEOMEAN($D7:$D28)-1) -> 0.036268859
A8: =+A7+1 -> 2000 | B8: 0.0583 | D8: =1+B8 -> 1.0583 | E8: =+D8-1 -> 0.0583 | F8: =+IF(TYPE(GEOMEAN($D8:$D9)-1)>1,"",GEOMEAN($D8:$D9)-1) -> 0.055245592 | G8: =+IF(TYPE(GEOMEAN($D8:$D10)-1)>1,"",GEOMEAN($D8:$D10)-1) -> 0.054095809 | H8: =+IF(TYPE(GEOMEAN($D8:$D11)-1)>1,"",GEOMEAN($D8:$D11)-1) -> 0.051386429 | I8: =+IF(TYPE(GEOMEAN($D8:$D12)-1)>1,"",GEOMEAN($D8:$D12)-1) -> 0.049703766 | J8: =+IF(TYPE(GEOMEAN($D8:$D13)-1)>1,"",GEOMEAN($D8:$D13)-1) -> 0.047878556 | K8: =+IF(TYPE(GEOMEAN($D8:$D14)-1)>1,"",GEOMEAN($D8:$D14)-1) -> 0.045783379 | L8: =+IF(TYPE(GEOMEAN($D8:$D15)-1)>1,"",GEOMEAN($D8:$D15)-1) -> 0.045058702 | M8: =+IF(TYPE(GEOMEAN($D8:$D16)-1)>1,"",GEOMEAN($D8:$D16)-1) -> 0.044941015 | N8: =+IF(TYPE(GEOMEAN($D8:$D17)-1)>1,"",GEOMEAN($D8:$D17)-1) -> 0.044405681 | O8: =+IF(TYPE(GEOMEAN($D8:$D18)-1)>1,"",GEOMEAN($D8:$D18)-1) -> 0.043913096 | P8: =+IF(TYPE(GEOMEAN($D8:$D19)-1)>1,"",GEOMEAN($D8:$D19)-1) -> 0.044791263 | Q8: =+IF(TYPE(GEOMEAN($D8:$D20)-1)>1,"",GEOMEAN($D8:$D20)-1) -> 0.045206329 | R8: =+IF(TYPE(GEOMEAN($D8:$D21)-1)>1,"",GEOMEAN($D8:$D21)-1) -> 0.045945328 | S8: =+IF(TYPE(GEOMEAN($D8:$D22)-1)>1,"",GEOMEAN($D8:$D22)-1) -> 0.045634996 | T8: =+IF(TYPE(GEOMEAN($D8:$D23)-1)>1,"",GEOMEAN($D8:$D23)-1) -> 0.043770582 | U8: =+IF(TYPE(GEOMEAN($D8:$D24)-1)>1,"",GEOMEAN($D8:$D24)-1) -> 0.04222472 | V8: =+IF(TYPE(GEOMEAN($D8:$D25)-1)>1,"",GEOMEAN($D8:$D25)-1) -> 0.040613458 | W8: =+IF(TYPE(GEOMEAN($D8:$D26)-1)>1,"",GEOMEAN($D8:$D26)-1) -> 0.03912533 | X8: =+IF(TYPE(GEOMEAN($D8:$D27)-1)>1,"",GEOMEAN($D8:$D27)-1) -> 0.037310826 | Y8: =+IF(TYPE(GEOMEAN($D8:$D28)-1)>1,"",GEOMEAN($D8:$D28)-1) -> 0.035689996 | Z8: =+IF(TYPE(GEOMEAN($D8:$D29)-1)>1,"",GEOMEAN($D8:$D29)-1) -> 0.034204659
A9: =+A8+1 -> 2001 | B9: 0.0522 | D9: =1+B9 -> 1.0522 | E9: =+D9-1 -> 0.0522 | F9: =+IF(TYPE(GEOMEAN($D9:$D10)-1)>1,"",GEOMEAN($D9:$D10)-1) -> 0.051999981 | G9: =+IF(TYPE(GEOMEAN($D9:$D11)-1)>1,"",GEOMEAN($D9:$D11)-1) -> 0.049091956 | H9: =+IF(TYPE(GEOMEAN($D9:$D12)-1)>1,"",GEOMEAN($D9:$D12)-1) -> 0.047565639 | I9: =+IF(TYPE(GEOMEAN($D9:$D13)-1)>1,"",GEOMEAN($D9:$D13)-1) -> 0.045806614 | J9: =+IF(TYPE(GEOMEAN($D9:$D14)-1)>1,"",GEOMEAN($D9:$D14)-1) -> 0.043711715 | K9: =+IF(TYPE(GEOMEAN($D9:$D15)-1)>1,"",GEOMEAN($D9:$D15)-1) -> 0.04318066 | L9: =+IF(TYPE(GEOMEAN($D9:$D16)-1)>1,"",GEOMEAN($D9:$D16)-1) -> 0.043283043 | M9: =+IF(TYPE(GEOMEAN($D9:$D17)-1)>1,"",GEOMEAN($D9:$D17)-1) -> 0.042873172 | N9: =+IF(TYPE(GEOMEAN($D9:$D18)-1)>1,"",GEOMEAN($D9:$D18)-1) -> 0.042485206 | O9: =+IF(TYPE(GEOMEAN($D9:$D19)-1)>1,"",GEOMEAN($D9:$D19)-1) -> 0.04357178 | P9: =+IF(TYPE(GEOMEAN($D9:$D20)-1)>1,"",GEOMEAN($D9:$D20)-1) -> 0.04412253 | Q9: =+IF(TYPE(GEOMEAN($D9:$D21)-1)>1,"",GEOMEAN($D9:$D21)-1) -> 0.045000964 | R9: =+IF(TYPE(GEOMEAN($D9:$D22)-1)>1,"",GEOMEAN($D9:$D22)-1) -> 0.044736174 | S9: =+IF(TYPE(GEOMEAN($D9:$D23)-1)>1,"",GEOMEAN($D9:$D23)-1) -> 0.042809078 | T9: =+IF(TYPE(GEOMEAN($D9:$D24)-1)>1,"",GEOMEAN($D9:$D24)-1) -> 0.041228162 | U9: =+IF(TYPE(GEOMEAN($D9:$D25)-1)>1,"",GEOMEAN($D9:$D25)-1) -> 0.039582327 | V9: =+IF(TYPE(GEOMEAN($D9:$D26)-1)>1,"",GEOMEAN($D9:$D26)-1) -> 0.038070316 | W9: =+IF(TYPE(GEOMEAN($D9:$D27)-1)>1,"",GEOMEAN($D9:$D27)-1) -> 0.036217737 | X9: =+IF(TYPE(GEOMEAN($D9:$D28)-1)>1,"",GEOMEAN($D9:$D28)-1) -> 0.034572262 | Y9: =+IF(TYPE(GEOMEAN($D9:$D29)-1)>1,"",GEOMEAN($D9:$D29)-1) -> 0.033071046 | Z9: =+IF(TYPE(GEOMEAN($D9:$D30)-1)>1,"",GEOMEAN($D9:$D30)-1) -> 0.032565225
A10: =+A9+1 -> 2002 | B10: 0.0518 | D10: =1+B10 -> 1.0518 | E10: =+D10-1 -> 0.0518 | F10: =+IF(TYPE(GEOMEAN($D10:$D11)-1)>1,"",GEOMEAN($D10:$D11)-1) -> 0.047541379 | G10: =+IF(TYPE(GEOMEAN($D10:$D12)-1)>1,"",GEOMEAN($D10:$D12)-1) -> 0.046025393 | H10: =+IF(TYPE(GEOMEAN($D10:$D13)-1)>1,"",GEOMEAN($D10:$D13)-1) -> 0.044214347 | I10: =+IF(TYPE(GEOMEAN($D10:$D14)-1)>1,"",GEOMEAN($D10:$D14)-1) -> 0.042022293 | J10: =+IF(TYPE(GEOMEAN($D10:$D15)-1)>1,"",GEOMEAN($D10:$D15)-1) -> 0.041684972 | K10: =+IF(TYPE(GEOMEAN($D10:$D16)-1)>1,"",GEOMEAN($D10:$D16)-1) -> 0.042015375 | L10: =+IF(TYPE(GEOMEAN($D10:$D17)-1)>1,"",GEOMEAN($D10:$D17)-1) -> 0.041713147 | M10: =+IF(TYPE(GEOMEAN($D10:$D18)-1)>1,"",GEOMEAN($D10:$D18)-1) -> 0.041411337 | N10: =+IF(TYPE(GEOMEAN($D10:$D19)-1)>1,"",GEOMEAN($D10:$D19)-1) -> 0.042712859 | O10: =+IF(TYPE(GEOMEAN($D10:$D20)-1)>1,"",GEOMEAN($D10:$D20)-1) -> 0.043391297 | P10: =+IF(TYPE(GEOMEAN($D10:$D21)-1)>1,"",GEOMEAN($D10:$D21)-1) -> 0.044403273 | Q10: =+IF(TYPE(GEOMEAN($D10:$D22)-1)>1,"",GEOMEAN($D10:$D22)-1) -> 0.044164231 | R10: =+IF(TYPE(GEOMEAN($D10:$D23)-1)>1,"",GEOMEAN($D10:$D23)-1) -> 0.042141513 | S10: =+IF(TYPE(GEOMEAN($D10:$D24)-1)>1,"",GEOMEAN($D10:$D24)-1) -> 0.040500787 | T10: =+IF(TYPE(GEOMEAN($D10:$D25)-1)>1,"",GEOMEAN($D10:$D25)-1) -> 0.038798765 | U10: =+IF(TYPE(GEOMEAN($D10:$D26)-1)>1,"",GEOMEAN($D10:$D26)-1) -> 0.037245092 | V10: =+IF(TYPE(GEOMEAN($D10:$D27)-1)>1,"",GEOMEAN($D10:$D27)-1) -> 0.035336986 | W10: =+IF(TYPE(GEOMEAN($D10:$D28)-1)>1,"",GEOMEAN($D10:$D28)-1) -> 0.033652711 | X10: =+IF(TYPE(GEOMEAN($D10:$D29)-1)>1,"",GEOMEAN($D10:$D29)-1) -> 0.03212378 | Y10: =+IF(TYPE(GEOMEAN($D10:$D30)-1)>1,"",GEOMEAN($D10:$D30)-1) -> 0.031639429 | Z10: =+IF(TYPE(GEOMEAN($D10:$D31)-1)>1,"",GEOMEAN($D10:$D31)-1) -> 0.031787414
A11: =+A10+1 -> 2003 | B11: 0.0433 | D11: =1+B11 -> 1.0433 | E11: =+D11-1 -> 0.0433 | F11: =+IF(TYPE(GEOMEAN($D11:$D12)-1)>1,"",GEOMEAN($D11:$D12)-1) -> 0.043149989 | G11: =+IF(TYPE(GEOMEAN($D11:$D13)-1)>1,"",GEOMEAN($D11:$D13)-1) -> 0.041697973 | H11: =+IF(TYPE(GEOMEAN($D11:$D14)-1)>1,"",GEOMEAN($D11:$D14)-1) -> 0.039592102 | I11: =+IF(TYPE(GEOMEAN($D11:$D15)-1)>1,"",GEOMEAN($D11:$D15)-1) -> 0.039673669 | J11: =+IF(TYPE(GEOMEAN($D11:$D16)-1)>1,"",GEOMEAN($D11:$D16)-1) -> 0.040393477 | K11: =+IF(TYPE(GEOMEAN($D11:$D17)-1)>1,"",GEOMEAN($D11:$D17)-1) -> 0.040280086 | L11: =+IF(TYPE(GEOMEAN($D11:$D18)-1)>1,"",GEOMEAN($D11:$D18)-1) -> 0.040119989 | M11: =+IF(TYPE(GEOMEAN($D11:$D19)-1)>1,"",GEOMEAN($D11:$D19)-1) -> 0.041708035 | N11: =+IF(TYPE(GEOMEAN($D11:$D20)-1)>1,"",GEOMEAN($D11:$D20)-1) -> 0.042554132 | O11: =+IF(TYPE(GEOMEAN($D11:$D21)-1)>1,"",GEOMEAN($D11:$D21)-1) -> 0.043733428 | P11: =+IF(TYPE(GEOMEAN($D11:$D22)-1)>1,"",GEOMEAN($D11:$D22)-1) -> 0.043530425 | Q11: =+IF(TYPE(GEOMEAN($D11:$D23)-1)>1,"",GEOMEAN($D11:$D23)-1) -> 0.041402237 | R11: =+IF(TYPE(GEOMEAN($D11:$D24)-1)>1,"",GEOMEAN($D11:$D24)-1) -> 0.03969836 | S11: =+IF(TYPE(GEOMEAN($D11:$D25)-1)>1,"",GEOMEAN($D11:$D25)-1) -> 0.037937752 | T11: =+IF(TYPE(GEOMEAN($D11:$D26)-1)>1,"",GEOMEAN($D11:$D26)-1) -> 0.036342127 | U11: =+IF(TYPE(GEOMEAN($D11:$D27)-1)>1,"",GEOMEAN($D11:$D27)-1) -> 0.034376638 | V11: =+IF(TYPE(GEOMEAN($D11:$D28)-1)>1,"",GEOMEAN($D11:$D28)-1) -> 0.032653759 | W11: =+IF(TYPE(GEOMEAN($D11:$D29)-1)>1,"",GEOMEAN($D11:$D29)-1) -> 0.031098447 | X11: =+IF(TYPE(GEOMEAN($D11:$D30)-1)>1,"",GEOMEAN($D11:$D30)-1) -> 0.030641607 | Y11: =+IF(TYPE(GEOMEAN($D11:$D31)-1)>1,"",GEOMEAN($D11:$D31)-1) -> 0.03084399 | Z11: =+IF(TYPE(GEOMEAN($D11:$D32)-1)>1,"",GEOMEAN($D11:$D32)-1) -> 0.030873799
A12: =+A11+1 -> 2004 | B12: 0.043 | D12: =1+B12 -> 1.043 | E12: =+D12-1 -> 0.043 | F12: =+IF(TYPE(GEOMEAN($D12:$D13)-1)>1,"",GEOMEAN($D12:$D13)-1) -> 0.040897882 | G12: =+IF(TYPE(GEOMEAN($D12:$D14)-1)>1,"",GEOMEAN($D12:$D14)-1) -> 0.038359067 | H12: =+IF(TYPE(GEOMEAN($D12:$D15)-1)>1,"",GEOMEAN($D12:$D15)-1) -> 0.038769057 | I12: =+IF(TYPE(GEOMEAN($D12:$D16)-1)>1,"",GEOMEAN($D12:$D16)-1) -> 0.039813145 | J12: =+IF(TYPE(GEOMEAN($D12:$D17)-1)>1,"",GEOMEAN($D12:$D17)-1) -> 0.039777618 | K12: =+IF(TYPE(GEOMEAN($D12:$D18)-1)>1,"",GEOMEAN($D12:$D18)-1) -> 0.039666494 | L12: =+IF(TYPE(GEOMEAN($D12:$D19)-1)>1,"",GEOMEAN($D12:$D19)-1) -> 0.04150921 | M12: =+IF(TYPE(GEOMEAN($D12:$D20)-1)>1,"",GEOMEAN($D12:$D20)-1) -> 0.042471291 | N12: =+IF(TYPE(GEOMEAN($D12:$D21)-1)>1,"",GEOMEAN($D12:$D21)-1) -> 0.043776781 | O12: =+IF(TYPE(GEOMEAN($D12:$D22)-1)>1,"",GEOMEAN($D12:$D22)-1) -> 0.043551375 | P12: =+IF(TYPE(GEOMEAN($D12:$D23)-1)>1,"",GEOMEAN($D12:$D23)-1) -> 0.041244246 | Q12: =+IF(TYPE(GEOMEAN($D12:$D24)-1)>1,"",GEOMEAN($D12:$D24)-1) -> 0.039421827 | R12: =+IF(TYPE(GEOMEAN($D12:$D25)-1)>1,"",GEOMEAN($D12:$D25)-1) -> 0.037555791 | S12: =+IF(TYPE(GEOMEAN($D12:$D26)-1)>1,"",GEOMEAN($D12:$D26)-1) -> 0.035879922 | T12: =+IF(TYPE(GEOMEAN($D12:$D27)-1)>1,"",GEOMEAN($D12:$D27)-1) -> 0.033821469 | U12: =+IF(TYPE(GEOMEAN($D12:$D28)-1)>1,"",GEOMEAN($D12:$D28)-1) -> 0.032030904 | V12: =+IF(TYPE(GEOMEAN($D12:$D29)-1)>1,"",GEOMEAN($D12:$D29)-1) -> 0.030424782 | W12: =+IF(TYPE(GEOMEAN($D12:$D30)-1)>1,"",GEOMEAN($D12:$D30)-1) -> 0.029979646 | X12: =+IF(TYPE(GEOMEAN($D12:$D31)-1)>1,"",GEOMEAN($D12:$D31)-1) -> 0.030225108 | Y12: =+IF(TYPE(GEOMEAN($D12:$D32)-1)>1,"",GEOMEAN($D12:$D32)-1) -> 0.030285781 | Z12: =+IF(TYPE(GEOMEAN($D12:$D33)-1)>1,"",GEOMEAN($D12:$D33)-1) -> 0.030372714
A13: =+A12+1 -> 2005 | B13: 0.0388 | D13: =1+B13 -> 1.0388 | E13: =+D13-1 -> 0.0388 | F13: =+IF(TYPE(GEOMEAN($D13:$D14)-1)>1,"",GEOMEAN($D13:$D14)-1) -> 0.03604635 | G13: =+IF(TYPE(GEOMEAN($D13:$D15)-1)>1,"",GEOMEAN($D13:$D15)-1) -> 0.037362561 | H13: =+IF(TYPE(GEOMEAN($D13:$D16)-1)>1,"",GEOMEAN($D13:$D16)-1) -> 0.039017954 | I13: =+IF(TYPE(GEOMEAN($D13:$D17)-1)>1,"",GEOMEAN($D13:$D17)-1) -> 0.039134337 | J13: =+IF(TYPE(GEOMEAN($D13:$D18)-1)>1,"",GEOMEAN($D13:$D18)-1) -> 0.039111946 | K13: =+IF(TYPE(GEOMEAN($D13:$D19)-1)>1,"",GEOMEAN($D13:$D19)-1) -> 0.041296414 | L13: =+IF(TYPE(GEOMEAN($D13:$D20)-1)>1,"",GEOMEAN($D13:$D20)-1) -> 0.042405221 | M13: =+IF(TYPE(GEOMEAN($D13:$D21)-1)>1,"",GEOMEAN($D13:$D21)-1) -> 0.043863125 | N13: =+IF(TYPE(GEOMEAN($D13:$D22)-1)>1,"",GEOMEAN($D13:$D22)-1) -> 0.043606529 | O13: =+IF(TYPE(GEOMEAN($D13:$D23)-1)>1,"",GEOMEAN($D13:$D23)-1) -> 0.041084779 | P13: =+IF(TYPE(GEOMEAN($D13:$D24)-1)>1,"",GEOMEAN($D13:$D24)-1) -> 0.0391242 | Q13: =+IF(TYPE(GEOMEAN($D13:$D25)-1)>1,"",GEOMEAN($D13:$D25)-1) -> 0.037138185 | R13: =+IF(TYPE(GEOMEAN($D13:$D26)-1)>1,"",GEOMEAN($D13:$D26)-1) -> 0.035373209 | S13: =+IF(TYPE(GEOMEAN($D13:$D27)-1)>1,"",GEOMEAN($D13:$D27)-1) -> 0.033212446 | T13: =+IF(TYPE(GEOMEAN($D13:$D28)-1)>1,"",GEOMEAN($D13:$D28)-1) -> 0.031349178 | U13: =+IF(TYPE(GEOMEAN($D13:$D29)-1)>1,"",GEOMEAN($D13:$D29)-1) -> 0.029689803 | V13: =+IF(TYPE(GEOMEAN($D13:$D30)-1)>1,"",GEOMEAN($D13:$D30)-1) -> 0.029261078 | W13: =+IF(TYPE(GEOMEAN($D13:$D31)-1)>1,"",GEOMEAN($D13:$D31)-1) -> 0.029557096 | X13: =+IF(TYPE(GEOMEAN($D13:$D32)-1)>1,"",GEOMEAN($D13:$D32)-1) -> 0.029654154 | Y13: =+IF(TYPE(GEOMEAN($D13:$D33)-1)>1,"",GEOMEAN($D13:$D33)-1) -> 0.029775242 | Z13: =+IF(TYPE(GEOMEAN($D13:$D34)-1)>1,"",GEOMEAN($D13:$D34)-1)
A14: =+A13+1 -> 2006 | B14: 0.0333 | D14: =1+B14 -> 1.0333 | E14: =+D14-1 -> 0.0333 | F14: =+IF(TYPE(GEOMEAN($D14:$D15)-1)>1,"",GEOMEAN($D14:$D15)-1) -> 0.036644587 | G14: =+IF(TYPE(GEOMEAN($D14:$D16)-1)>1,"",GEOMEAN($D14:$D16)-1) -> 0.039090615 | H14: =+IF(TYPE(GEOMEAN($D14:$D17)-1)>1,"",GEOMEAN($D14:$D17)-1) -> 0.039217938 | I14: =+IF(TYPE(GEOMEAN($D14:$D18)-1)>1,"",GEOMEAN($D14:$D18)-1) -> 0.039174347 | J14: =+IF(TYPE(GEOMEAN($D14:$D19)-1)>1,"",GEOMEAN($D14:$D19)-1) -> 0.041713066 | K14: =+IF(TYPE(GEOMEAN($D14:$D20)-1)>1,"",GEOMEAN($D14:$D20)-1) -> 0.042921273 | L14: =+IF(TYPE(GEOMEAN($D14:$D21)-1)>1,"",GEOMEAN($D14:$D21)-1) -> 0.044497749 | M14: =+IF(TYPE(GEOMEAN($D14:$D22)-1)>1,"",GEOMEAN($D14:$D22)-1) -> 0.044141959 | N14: =+IF(TYPE(GEOMEAN($D14:$D23)-1)>1,"",GEOMEAN($D14:$D23)-1) -> 0.041313533 | O14: =+IF(TYPE(GEOMEAN($D14:$D24)-1)>1,"",GEOMEAN($D14:$D24)-1) -> 0.039153678 | P14: =+IF(TYPE(GEOMEAN($D14:$D25)-1)>1,"",GEOMEAN($D14:$D25)-1) -> 0.03699982 | Q14: =+IF(TYPE(GEOMEAN($D14:$D26)-1)>1,"",GEOMEAN($D14:$D26)-1) -> 0.035110078 | R14: =+IF(TYPE(GEOMEAN($D14:$D27)-1)>1,"",GEOMEAN($D14:$D27)-1) -> 0.032814487 | S14: =+IF(TYPE(GEOMEAN($D14:$D28)-1)>1,"",GEOMEAN($D14:$D28)-1) -> 0.030854361 | T14: =+IF(TYPE(GEOMEAN($D14:$D29)-1)>1,"",GEOMEAN($D14:$D29)-1) -> 0.029123076 | U14: =+IF(TYPE(GEOMEAN($D14:$D30)-1)>1,"",GEOMEAN($D14:$D30)-1) -> 0.028702701 | V14: =+IF(TYPE(GEOMEAN($D14:$D31)-1)>1,"",GEOMEAN($D14:$D31)-1) -> 0.02904602 | W14: =+IF(TYPE(GEOMEAN($D14:$D32)-1)>1,"",GEOMEAN($D14:$D32)-1) -> 0.029175031 | X14: =+IF(TYPE(GEOMEAN($D14:$D33)-1)>1,"",GEOMEAN($D14:$D33)-1) -> 0.029326068 | Y14: =+IF(TYPE(GEOMEAN($D14:$D34)-1)>1,"",GEOMEAN($D14:$D34)-1) | Z14: =+IF(TYPE(GEOMEAN($D14:$D35)-1)>1,"",GEOMEAN($D14:$D35)-1)
A15: =+A14+1 -> 2007 | B15: 0.04 | D15: =1+B15 -> 1.04 | E15: =+D15-1 -> 0.04 | F15: =+IF(TYPE(GEOMEAN($D15:$D16)-1)>1,"",GEOMEAN($D15:$D16)-1) -> 0.041998081 | G15: =+IF(TYPE(GEOMEAN($D15:$D17)-1)>1,"",GEOMEAN($D15:$D17)-1) -> 0.041198106 | H15: =+IF(TYPE(GEOMEAN($D15:$D18)-1)>1,"",GEOMEAN($D15:$D18)-1) -> 0.040648144 | I15: =+IF(TYPE(GEOMEAN($D15:$D19)-1)>1,"",GEOMEAN($D15:$D19)-1) -> 0.043403882 | J15: =+IF(TYPE(GEOMEAN($D15:$D20)-1)>1,"",GEOMEAN($D15:$D20)-1) -> 0.044533506 | K15: =+IF(TYPE(GEOMEAN($D15:$D21)-1)>1,"",GEOMEAN($D15:$D21)-1) -> 0.046107302 | L15: =+IF(TYPE(GEOMEAN($D15:$D22)-1)>1,"",GEOMEAN($D15:$D22)-1) -> 0.045505178 | M15: =+IF(TYPE(GEOMEAN($D15:$D23)-1)>1,"",GEOMEAN($D15:$D23)-1) -> 0.042207753 | N15: =+IF(TYPE(GEOMEAN($D15:$D24)-1)>1,"",GEOMEAN($D15:$D24)-1) -> 0.039740867 | O15: =+IF(TYPE(GEOMEAN($D15:$D25)-1)>1,"",GEOMEAN($D15:$D25)-1) -> 0.037336824 | P15: =+IF(TYPE(GEOMEAN($D15:$D26)-1)>1,"",GEOMEAN($D15:$D26)-1) -> 0.035261061 | Q15: =+IF(TYPE(GEOMEAN($D15:$D27)-1)>1,"",GEOMEAN($D15:$D27)-1) -> 0.03277715 | R15: =+IF(TYPE(GEOMEAN($D15:$D28)-1)>1,"",GEOMEAN($D15:$D28)-1) -> 0.030679894 | S15: =+IF(TYPE(GEOMEAN($D15:$D29)-1)>1,"",GEOMEAN($D15:$D29)-1) -> 0.028845216 | T15: =+IF(TYPE(GEOMEAN($D15:$D30)-1)>1,"",GEOMEAN($D15:$D30)-1) -> 0.02841605 | U15: =+IF(TYPE(GEOMEAN($D15:$D31)-1)>1,"",GEOMEAN($D15:$D31)-1) -> 0.028796331 | V15: =+IF(TYPE(GEOMEAN($D15:$D32)-1)>1,"",GEOMEAN($D15:$D32)-1) -> 0.028946349 | W15: =+IF(TYPE(GEOMEAN($D15:$D33)-1)>1,"",GEOMEAN($D15:$D33)-1) -> 0.029117338 | X15: =+IF(TYPE(GEOMEAN($D15:$D34)-1)>1,"",GEOMEAN($D15:$D34)-1) | Y15: =+IF(TYPE(GEOMEAN($D15:$D35)-1)>1,"",GEOMEAN($D15:$D35)-1) | Z15: =+IF(TYPE(GEOMEAN($D15:$D36)-1)>1,"",GEOMEAN($D15:$D36)-1)
A16: =+A15+1 -> 2008 | B16: 0.044 | D16: =1+B16 -> 1.044 | E16: =+D16-1 -> 0.044 | F16: =+IF(TYPE(GEOMEAN($D16:$D17)-1)>1,"",GEOMEAN($D16:$D17)-1) -> 0.041797677 | G16: =+IF(TYPE(GEOMEAN($D16:$D18)-1)>1,"",GEOMEAN($D16:$D18)-1) -> 0.040864282 | H16: =+IF(TYPE(GEOMEAN($D16:$D19)-1)>1,"",GEOMEAN($D16:$D19)-1) -> 0.044256592 | I16: =+IF(TYPE(GEOMEAN($D16:$D20)-1)>1,"",GEOMEAN($D16:$D20)-1) -> 0.045442576 | J16: =+IF(TYPE(GEOMEAN($D16:$D21)-1)>1,"",GEOMEAN($D16:$D21)-1) -> 0.047128667 | K16: =+IF(TYPE(GEOMEAN($D16:$D22)-1)>1,"",GEOMEAN($D16:$D22)-1) -> 0.046294007 | L16: =+IF(TYPE(GEOMEAN($D16:$D23)-1)>1,"",GEOMEAN($D16:$D23)-1) -> 0.042484051 | M16: =+IF(TYPE(GEOMEAN($D16:$D24)-1)>1,"",GEOMEAN($D16:$D24)-1) -> 0.039712078 | N16: =+IF(TYPE(GEOMEAN($D16:$D25)-1)>1,"",GEOMEAN($D16:$D25)-1) -> 0.037070881 | O16: =+IF(TYPE(GEOMEAN($D16:$D26)-1)>1,"",GEOMEAN($D16:$D26)-1) -> 0.034831321 | P16: =+IF(TYPE(GEOMEAN($D16:$D27)-1)>1,"",GEOMEAN($D16:$D27)-1) -> 0.032177515 | Q16: =+IF(TYPE(GEOMEAN($D16:$D28)-1)>1,"",GEOMEAN($D16:$D28)-1) -> 0.029966432 | R16: =+IF(TYPE(GEOMEAN($D16:$D29)-1)>1,"",GEOMEAN($D16:$D29)-1) -> 0.028053039 | S16: =+IF(TYPE(GEOMEAN($D16:$D30)-1)>1,"",GEOMEAN($D16:$D30)-1) -> 0.02764839 | T16: =+IF(TYPE(GEOMEAN($D16:$D31)-1)>1,"",GEOMEAN($D16:$D31)-1) -> 0.028100123 | U16: =+IF(TYPE(GEOMEAN($D16:$D32)-1)>1,"",GEOMEAN($D16:$D32)-1) -> 0.028299805 | V16: =+IF(TYPE(GEOMEAN($D16:$D33)-1)>1,"",GEOMEAN($D16:$D33)-1) -> 0.028516096 | W16: =+IF(TYPE(GEOMEAN($D16:$D34)-1)>1,"",GEOMEAN($D16:$D34)-1) | X16: =+IF(TYPE(GEOMEAN($D16:$D35)-1)>1,"",GEOMEAN($D16:$D35)-1) | Y16: =+IF(TYPE(GEOMEAN($D16:$D36)-1)>1,"",GEOMEAN($D16:$D36)-1) | Z16: =+IF(TYPE(GEOMEAN($D16:$D37)-1)>1,"",GEOMEAN($D16:$D37)-1)
A17: =+A16+1 -> 2009 | B17: 0.0396 | D17: =1+B17 -> 1.0396 | E17: =+D17-1 -> 0.0396 | F17: =+IF(TYPE(GEOMEAN($D17:$D18)-1)>1,"",GEOMEAN($D17:$D18)-1) -> 0.039299957 | G17: =+IF(TYPE(GEOMEAN($D17:$D19)-1)>1,"",GEOMEAN($D17:$D19)-1) -> 0.044342136 | H17: =+IF(TYPE(GEOMEAN($D17:$D20)-1)>1,"",GEOMEAN($D17:$D20)-1) -> 0.045803532 | I17: =+IF(TYPE(GEOMEAN($D17:$D21)-1)>1,"",GEOMEAN($D17:$D21)-1) -> 0.047755525 | J17: =+IF(TYPE(GEOMEAN($D17:$D22)-1)>1,"",GEOMEAN($D17:$D22)-1) -> 0.046676832 | K17: =+IF(TYPE(GEOMEAN($D17:$D23)-1)>1,"",GEOMEAN($D17:$D23)-1) -> 0.042267667 | L17: =+IF(TYPE(GEOMEAN($D17:$D24)-1)>1,"",GEOMEAN($D17:$D24)-1) -> 0.039177328 | M17: =+IF(TYPE(GEOMEAN($D17:$D25)-1)>1,"",GEOMEAN($D17:$D25)-1) -> 0.036303824 | N17: =+IF(TYPE(GEOMEAN($D17:$D26)-1)>1,"",GEOMEAN($D17:$D26)-1) -> 0.033918893 | O17: =+IF(TYPE(GEOMEAN($D17:$D27)-1)>1,"",GEOMEAN($D17:$D27)-1) -> 0.031109405 | P17: =+IF(TYPE(GEOMEAN($D17:$D28)-1)>1,"",GEOMEAN($D17:$D28)-1) -> 0.028805518 | Q17: =+IF(TYPE(GEOMEAN($D17:$D29)-1)>1,"",GEOMEAN($D17:$D29)-1) -> 0.026836487 | R17: =+IF(TYPE(GEOMEAN($D17:$D30)-1)>1,"",GEOMEAN($D17:$D30)-1) -> 0.026490266 | S17: =+IF(TYPE(GEOMEAN($D17:$D31)-1)>1,"",GEOMEAN($D17:$D31)-1) -> 0.027048782 | T17: =+IF(TYPE(GEOMEAN($D17:$D32)-1)>1,"",GEOMEAN($D17:$D32)-1) -> 0.02732642 | U17: =+IF(TYPE(GEOMEAN($D17:$D33)-1)>1,"",GEOMEAN($D17:$D33)-1) -> 0.027612463 | V17: =+IF(TYPE(GEOMEAN($D17:$D34)-1)>1,"",GEOMEAN($D17:$D34)-1) | W17: =+IF(TYPE(GEOMEAN($D17:$D35)-1)>1,"",GEOMEAN($D17:$D35)-1) | X17: =+IF(TYPE(GEOMEAN($D17:$D36)-1)>1,"",GEOMEAN($D17:$D36)-1) | Y17: =+IF(TYPE(GEOMEAN($D17:$D37)-1)>1,"",GEOMEAN($D17:$D37)-1) | Z17: =+IF(TYPE(GEOMEAN($D17:$D38)-1)>1,"",GEOMEAN($D17:$D38)-1)
A18: =+A17+1 -> 2010 | B18: 0.039 | D18: =1+B18 -> 1.039 | E18: =+D18-1 -> 0.039 | F18: =+IF(TYPE(GEOMEAN($D18:$D19)-1)>1,"",GEOMEAN($D18:$D19)-1) -> 0.04672131 | G18: =+IF(TYPE(GEOMEAN($D18:$D20)-1)>1,"",GEOMEAN($D18:$D20)-1) -> 0.047879591 | H18: =+IF(TYPE(GEOMEAN($D18:$D21)-1)>1,"",GEOMEAN($D18:$D21)-1) -> 0.049804383 | I18: =+IF(TYPE(GEOMEAN($D18:$D22)-1)>1,"",GEOMEAN($D18:$D22)-1) -> 0.048097968 | J18: =+IF(TYPE(GEOMEAN($D18:$D23)-1)>1,"",GEOMEAN($D18:$D23)-1) -> 0.042712943 | K18: =+IF(TYPE(GEOMEAN($D18:$D24)-1)>1,"",GEOMEAN($D18:$D24)-1) -> 0.03911696 | L18: =+IF(TYPE(GEOMEAN($D18:$D25)-1)>1,"",GEOMEAN($D18:$D25)-1) -> 0.035892537 | M18: =+IF(TYPE(GEOMEAN($D18:$D26)-1)>1,"",GEOMEAN($D18:$D26)-1) -> 0.033289579 | N18: =+IF(TYPE(GEOMEAN($D18:$D27)-1)>1,"",GEOMEAN($D18:$D27)-1) -> 0.030264169 | O18: =+IF(TYPE(GEOMEAN($D18:$D28)-1)>1,"",GEOMEAN($D18:$D28)-1) -> 0.027829777 | P18: =+IF(TYPE(GEOMEAN($D18:$D29)-1)>1,"",GEOMEAN($D18:$D29)-1) -> 0.025779961 | Q18: =+IF(TYPE(GEOMEAN($D18:$D30)-1)>1,"",GEOMEAN($D18:$D30)-1) -> 0.025488699 | R18: =+IF(TYPE(GEOMEAN($D18:$D31)-1)>1,"",GEOMEAN($D18:$D31)-1) -> 0.026158087 | S18: =+IF(TYPE(GEOMEAN($D18:$D32)-1)>1,"",GEOMEAN($D18:$D32)-1) -> 0.026513352 | T18: =+IF(TYPE(GEOMEAN($D18:$D33)-1)>1,"",GEOMEAN($D18:$D33)-1) -> 0.026867848 | U18: =+IF(TYPE(GEOMEAN($D18:$D34)-1)>1,"",GEOMEAN($D18:$D34)-1) | V18: =+IF(TYPE(GEOMEAN($D18:$D35)-1)>1,"",GEOMEAN($D18:$D35)-1) | W18: =+IF(TYPE(GEOMEAN($D18:$D36)-1)>1,"",GEOMEAN($D18:$D36)-1) | X18: =+IF(TYPE(GEOMEAN($D18:$D37)-1)>1,"",GEOMEAN($D18:$D37)-1) | Y18: =+IF(TYPE(GEOMEAN($D18:$D38)-1)>1,"",GEOMEAN($D18:$D38)-1) | Z18: =+IF(TYPE(GEOMEAN($D18:$D39)-1)>1,"",GEOMEAN($D18:$D39)-1)
A19: =+A18+1 -> 2011 | B19: 0.0545 | D19: =1+B19 -> 1.0545 | E19: =+D19-1 -> 0.0545 | F19: =+IF(TYPE(GEOMEAN($D19:$D20)-1)>1,"",GEOMEAN($D19:$D20)-1) -> 0.052347804 | G19: =+IF(TYPE(GEOMEAN($D19:$D21)-1)>1,"",GEOMEAN($D19:$D21)-1) -> 0.053430754 | H19: =+IF(TYPE(GEOMEAN($D19:$D22)-1)>1,"",GEOMEAN($D19:$D22)-1) -> 0.050384881 | I19: =+IF(TYPE(GEOMEAN($D19:$D23)-1)>1,"",GEOMEAN($D19:$D23)-1) -> 0.043457122 | J19: =+IF(TYPE(GEOMEAN($D19:$D24)-1)>1,"",GEOMEAN($D19:$D24)-1) -> 0.039136455 | K19: =+IF(TYPE(GEOMEAN($D19:$D25)-1)>1,"",GEOMEAN($D19:$D25)-1) -> 0.035449373 | L19: =+IF(TYPE(GEOMEAN($D19:$D26)-1)>1,"",GEOMEAN($D19:$D26)-1) -> 0.032577987 | M19: =+IF(TYPE(GEOMEAN($D19:$D27)-1)>1,"",GEOMEAN($D19:$D27)-1) -> 0.029298066 | N19: =+IF(TYPE(GEOMEAN($D19:$D28)-1)>1,"",GEOMEAN($D19:$D28)-1) -> 0.026719381 | O19: =+IF(TYPE(GEOMEAN($D19:$D29)-1)>1,"",GEOMEAN($D19:$D29)-1) -> 0.024586512 | P19: =+IF(TYPE(GEOMEAN($D19:$D30)-1)>1,"",GEOMEAN($D19:$D30)-1) -> 0.02437072 | Q19: =+IF(TYPE(GEOMEAN($D19:$D31)-1)>1,"",GEOMEAN($D19:$D31)-1) -> 0.025176847 | R19: =+IF(TYPE(GEOMEAN($D19:$D32)-1)>1,"",GEOMEAN($D19:$D32)-1) -> 0.025627213 | S19: =+IF(TYPE(GEOMEAN($D19:$D33)-1)>1,"",GEOMEAN($D19:$D33)-1) -> 0.026064093 | T19: =+IF(TYPE(GEOMEAN($D19:$D34)-1)>1,"",GEOMEAN($D19:$D34)-1) | U19: =+IF(TYPE(GEOMEAN($D19:$D35)-1)>1,"",GEOMEAN($D19:$D35)-1) | V19: =+IF(TYPE(GEOMEAN($D19:$D36)-1)>1,"",GEOMEAN($D19:$D36)-1) | W19: =+IF(TYPE(GEOMEAN($D19:$D37)-1)>1,"",GEOMEAN($D19:$D37)-1) | X19: =+IF(TYPE(GEOMEAN($D19:$D38)-1)>1,"",GEOMEAN($D19:$D38)-1) | Y19: =+IF(TYPE(GEOMEAN($D19:$D39)-1)>1,"",GEOMEAN($D19:$D39)-1) | Z19: =+IF(TYPE(GEOMEAN($D19:$D40)-1)>1,"",GEOMEAN($D19:$D40)-1)
... A33: =+A32+1 -> 2025 | B33: 0.0322 | D33: =1+B33 -> 1.0322 | E33: =+D33-1 -> 0.0322 | F33: =+IF(TYPE(GEOMEAN($D33:$D34)-1)>1,"",GEOMEAN($D33:$D34)-1) | G33: =+IF(TYPE(GEOMEAN($D33:$D35)-1)>1,"",GEOMEAN($D33:$D35)-1) | H33: =+IF(TYPE(GEOMEAN($D33:$D36)-1)>1,"",GEOMEAN($D33:$D36)-1) | I33: =+IF(TYPE(GEOMEAN($D33:$D37)-1)>1,"",GEOMEAN($D33:$D37)-1) | J33: =+IF(TYPE(GEOMEAN($D33:$D38)-1)>1,"",GEOMEAN($D33:$D38)-1) | K33: =+IF(TYPE(GEOMEAN($D33:$D39)-1)>1,"",GEOMEAN($D33:$D39)-1) | L33: =+IF(TYPE(GEOMEAN($D33:$D40)-1)>1,"",GEOMEAN($D33:$D40)-1) | M33: =+IF(TYPE(GEOMEAN($D33:$D41)-1)>1,"",GEOMEAN($D33:$D41)-1) | N33: =+IF(TYPE(GEOMEAN($D33:$D42)-1)>1,"",GEOMEAN($D33:$D42)-1) | O33: =+IF(TYPE(GEOMEAN($D33:$D43)-1)>1,"",GEOMEAN($D33:$D43)-1) | P33: =+IF(TYPE(GEOMEAN($D33:$D44)-1)>1,"",GEOMEAN($D33:$D44)-1) | Q33: =+IF(TYPE(GEOMEAN($D33:$D45)-1)>1,"",GEOMEAN($D33:$D45)-1) | R33: =+IF(TYPE(GEOMEAN($D33:$D46)-1)>1,"",GEOMEAN($D33:$D46)-1) | S33: =+IF(TYPE(GEOMEAN($D33:$D47)-1)>1,"",GEOMEAN($D33:$D47)-1) | T33: =+IF(TYPE(GEOMEAN($D33:$D48)-1)>1,"",GEOMEAN($D33:$D48)-1) | U33: =+IF(TYPE(GEOMEAN($D33:$D49)-1)>1,"",GEOMEAN($D33:$D49)-1) | V33: =+IF(TYPE(GEOMEAN($D33:$D50)-1)>1,"",GEOMEAN($D33:$D50)-1) | W33: =+IF(TYPE(GEOMEAN($D33:$D51)-1)>1,"",GEOMEAN($D33:$D51)-1) | X33: =+IF(TYPE(GEOMEAN($D33:$D52)-1)>1,"",GEOMEAN($D33:$D52)-1) | Y33: =+IF(TYPE(GEOMEAN($D33:$D53)-1)>1,"",GEOMEAN($D33:$D53)-1) | Z33: =+IF(TYPE(GEOMEAN($D33:$D54)-1)>1,"",GEOMEAN($D33:$D54)-1)
D34: 0 | P34: =+IF(TYPE(GEOMEAN($D34:$D47)-1)>1,"",GEOMEAN($D34:$D47)-1)
B36: medias aritméticas desde 1999 | E36: =+AVERAGE(E7:E33) -> 0.034260407 | F36: =+AVERAGE(F7:F33) -> 0.034016485 | G36: =+AVERAGE(G7:G33) -> 0.033633145 | H36: =+AVERAGE(H7:H33) -> 0.03321447 | I36: =+AVERAGE(I7:I33) -> 0.032874215 | J36: =+AVERAGE(J7:J33) -> 0.032770134 | K36: =+AVERAGE(K7:K33) -> 0.032815544 | L36: =+AVERAGE(L7:L33) -> 0.032998783 | ... Z36: =+AVERAGE(Z7:Z33) -> 0.032678778
B37: 1+ tanto acumulado | E37: =1+E36 -> 1.0342604 | F37: =+E37*(1+F36) -> 1.0694423 | G37: =+F37*(1+G36) -> 1.105411 | H37: =+G37*(1+H36) -> 1.1421267 | I37: =+H37*(1+I36) -> 1.1796732 | J37: =+I37*(1+J36) -> 1.2183312 | K37: =+J37*(1+K36) -> 1.2583114 | L37: =+K37*(1+L36) -> 1.2998342 | M37: =+L37*(1+M36) -> 1.3430833 | ... Z37: =+Y37*(1+Z36) -> 2.067691
B38: tanto acumulado | E38: =+E37-1 -> 0.034260407 | F38: =+F37-1 -> 0.069442311 | G38: =+G37-1 -> 0.10541102 | H38: =+H37-1 -> 0.14212666 | I38: =+I37-1 -> 0.17967318 | J38: =+J37-1 -> 0.21833123 | K38: =+K37-1 -> 0.25831143 | L38: =+L37-1 -> 0.29983417 | ... Z38: =+Z37-1 -> 1.067691

Sheet ipc
E5: HORIZONTE DE INVERSIÓN
D6: 1+r medio | E6: 1 | F6: =+E6+1 -> 2 | G6: =+F6+1 -> 3 | H6: =+G6+1 -> 4 | I6: =+H6+1 -> 5 | J6: =+I6+1 -> 6 | K6: =+J6+1 -> 7 | L6: =+K6+1 -> 8 | M6: =+L6+1 -> 9 | ... Z6: =+Y6+1 -> 22
A7: 1999 | B7: 0.029176995 | D7: =1+B7 -> 1.029177 | E7: =+D7-1 -> 0.029176995 | F7: =+IF(TYPE(GEOMEAN($D7:$D8)-1)>1,"",GEOMEAN($D7:$D8)-1) -> 0.034358756 | G7: =+IF(TYPE(GEOMEAN($D7:$D9)-1)>1,"",GEOMEAN($D7:$D9)-1) -> 0.031927918 | H7: =+IF(TYPE(GEOMEAN($D7:$D10)-1)>1,"",GEOMEAN($D7:$D10)-1) -> 0.034267179 | I7: =+IF(TYPE(GEOMEAN($D7:$D11)-1)>1,"",GEOMEAN($D7:$D11)-1) -> 0.032601036 | J7: =+IF(TYPE(GEOMEAN($D7:$D12)-1)>1,"",GEOMEAN($D7:$D12)-1) -> 0.032551829 | K7: =+IF(TYPE(GEOMEAN($D7:$D13)-1)>1,"",GEOMEAN($D7:$D13)-1) -> 0.033246364 | L7: =+IF(TYPE(GEOMEAN($D7:$D14)-1)>1,"",GEOMEAN($D7:$D14)-1) -> 0.032419073 | M7: =+IF(TYPE(GEOMEAN($D7:$D15)-1)>1,"",GEOMEAN($D7:$D15)-1) -> 0.033505481 | N7: =+IF(TYPE(GEOMEAN($D7:$D16)-1)>1,"",GEOMEAN($D7:$D16)-1) -> 0.031571836 | O7: =+IF(TYPE(GEOMEAN($D7:$D17)-1)>1,"",GEOMEAN($D7:$D17)-1) -> 0.029394743 | P7: =+IF(TYPE(GEOMEAN($D7:$D18)-1)>1,"",GEOMEAN($D7:$D18)-1) -> 0.029434736 | Q7: =+IF(TYPE(GEOMEAN($D7:$D19)-1)>1,"",GEOMEAN($D7:$D19)-1) -> 0.028997441 | R7: =+IF(TYPE(GEOMEAN($D7:$D20)-1)>1,"",GEOMEAN($D7:$D20)-1) -> 0.028973457 | S7: =+IF(TYPE(GEOMEAN($D7:$D21)-1)>1,"",GEOMEAN($D7:$D21)-1) -> 0.027189925 | T7: =+IF(TYPE(GEOMEAN($D7:$D22)-1)>1,"",GEOMEAN($D7:$D22)-1) -> 0.024802115 | U7: =+IF(TYPE(GEOMEAN($D7:$D23)-1)>1,"",GEOMEAN($D7:$D23)-1) -> 0.023332713 | V7: =+IF(TYPE(GEOMEAN($D7:$D24)-1)>1,"",GEOMEAN($D7:$D24)-1) -> 0.022906897 | W7: =+IF(TYPE(GEOMEAN($D7:$D25)-1)>1,"",GEOMEAN($D7:$D25)-1) -> 0.022284327 | X7: =+IF(TYPE(GEOMEAN($D7:$D26)-1)>1,"",GEOMEAN($D7:$D26)-1) -> 0.021760142 | Y7: =+IF(TYPE(GEOMEAN($D7:$D27)-1)>1,"",GEOMEAN($D7:$D27)-1) -> 0.021096376 | Z7: =+IF(TYPE(GEOMEAN($D7:$D28)-1)>1,"",GEOMEAN($D7:$D28)-1) -> 0.019876699
A8: =+A7+1 -> 2000 | B8: 0.039566607 | D8: =1+B8 -> 1.0395666 | E8: =+D8-1 -> 0.039566607 | F8: =+IF(TYPE(GEOMEAN($D8:$D9)-1)>1,"",GEOMEAN($D8:$D9)-1) -> 0.033306135 | G8: =+IF(TYPE(GEOMEAN($D8:$D10)-1)>1,"",GEOMEAN($D8:$D10)-1) -> 0.035969495 | H8: =+IF(TYPE(GEOMEAN($D8:$D11)-1)>1,"",GEOMEAN($D8:$D11)-1) -> 0.033458825 | I8: =+IF(TYPE(GEOMEAN($D8:$D12)-1)>1,"",GEOMEAN($D8:$D12)-1) -> 0.033228123 | J8: =+IF(TYPE(GEOMEAN($D8:$D13)-1)>1,"",GEOMEAN($D8:$D13)-1) -> 0.033926155 | K8: =+IF(TYPE(GEOMEAN($D8:$D14)-1)>1,"",GEOMEAN($D8:$D14)-1) -> 0.03288306 | L8: =+IF(TYPE(GEOMEAN($D8:$D15)-1)>1,"",GEOMEAN($D8:$D15)-1) -> 0.03404782 | M8: =+IF(TYPE(GEOMEAN($D8:$D16)-1)>1,"",GEOMEAN($D8:$D16)-1) -> 0.031838274 | N8: =+IF(TYPE(GEOMEAN($D8:$D17)-1)>1,"",GEOMEAN($D8:$D17)-1) -> 0.029416521 | O8: =+IF(TYPE(GEOMEAN($D8:$D18)-1)>1,"",GEOMEAN($D8:$D18)-1) -> 0.02945817 | P8: =+IF(TYPE(GEOMEAN($D8:$D19)-1)>1,"",GEOMEAN($D8:$D19)-1) -> 0.028982479 | Q8: =+IF(TYPE(GEOMEAN($D8:$D20)-1)>1,"",GEOMEAN($D8:$D20)-1) -> 0.028957802 | R8: =+IF(TYPE(GEOMEAN($D8:$D21)-1)>1,"",GEOMEAN($D8:$D21)-1) -> 0.027048138 | S8: =+IF(TYPE(GEOMEAN($D8:$D22)-1)>1,"",GEOMEAN($D8:$D22)-1) -> 0.024511118 | T8: =+IF(TYPE(GEOMEAN($D8:$D23)-1)>1,"",GEOMEAN($D8:$D23)-1) -> 0.022968549 | U8: =+IF(TYPE(GEOMEAN($D8:$D24)-1)>1,"",GEOMEAN($D8:$D24)-1) -> 0.022539259 | V8: =+IF(TYPE(GEOMEAN($D8:$D25)-1)>1,"",GEOMEAN($D8:$D25)-1) -> 0.021902758 | W8: =+IF(TYPE(GEOMEAN($D8:$D26)-1)>1,"",GEOMEAN($D8:$D26)-1) -> 0.021371266 | X8: =+IF(TYPE(GEOMEAN($D8:$D27)-1)>1,"",GEOMEAN($D8:$D27)-1) -> 0.020694015 | Y8: =+IF(TYPE(GEOMEAN($D8:$D28)-1)>1,"",GEOMEAN($D8:$D28)-1) -> 0.01943593 | Z8: =+IF(TYPE(GEOMEAN($D8:$D29)-1)>1,"",GEOMEAN($D8:$D29)-1) -> 0.021489976
A9: =+A8+1 -> 2001 | B9: 0.027083365 | D9: =1+B9 -> 1.0270834 | E9: =+D9-1 -> 0.027083365 | F9: =+IF(TYPE(GEOMEAN($D9:$D10)-1)>1,"",GEOMEAN($D9:$D10)-1) -> 0.034175609 | G9: =+IF(TYPE(GEOMEAN($D9:$D11)-1)>1,"",GEOMEAN($D9:$D11)-1) -> 0.031430883 | H9: =+IF(TYPE(GEOMEAN($D9:$D12)-1)>1,"",GEOMEAN($D9:$D12)-1) -> 0.03164955 | I9: =+IF(TYPE(GEOMEAN($D9:$D13)-1)>1,"",GEOMEAN($D9:$D13)-1) -> 0.032801742 | J9: =+IF(TYPE(GEOMEAN($D9:$D14)-1)>1,"",GEOMEAN($D9:$D14)-1) -> 0.031773321 | K9: =+IF(TYPE(GEOMEAN($D9:$D15)-1)>1,"",GEOMEAN($D9:$D15)-1) -> 0.033261818 | L9: =+IF(TYPE(GEOMEAN($D9:$D16)-1)>1,"",GEOMEAN($D9:$D16)-1) -> 0.03087628 | M9: =+IF(TYPE(GEOMEAN($D9:$D17)-1)>1,"",GEOMEAN($D9:$D17)-1) -> 0.028294869 | N9: =+IF(TYPE(GEOMEAN($D9:$D18)-1)>1,"",GEOMEAN($D9:$D18)-1) -> 0.028452748 | O9: =+IF(TYPE(GEOMEAN($D9:$D19)-1)>1,"",GEOMEAN($D9:$D19)-1) -> 0.028025646 | P9: =+IF(TYPE(GEOMEAN($D9:$D20)-1)>1,"",GEOMEAN($D9:$D20)-1) -> 0.028078638 | Q9: =+IF(TYPE(GEOMEAN($D9:$D21)-1)>1,"",GEOMEAN($D9:$D21)-1) -> 0.026091446 | R9: =+IF(TYPE(GEOMEAN($D9:$D22)-1)>1,"",GEOMEAN($D9:$D22)-1) -> 0.023444107 | S9: =+IF(TYPE(GEOMEAN($D9:$D23)-1)>1,"",GEOMEAN($D9:$D23)-1) -> 0.021871482 | T9: =+IF(TYPE(GEOMEAN($D9:$D24)-1)>1,"",GEOMEAN($D9:$D24)-1) -> 0.021484358 | U9: =+IF(TYPE(GEOMEAN($D9:$D25)-1)>1,"",GEOMEAN($D9:$D25)-1) -> 0.020873105 | V9: =+IF(TYPE(GEOMEAN($D9:$D26)-1)>1,"",GEOMEAN($D9:$D26)-1) -> 0.020369803 | W9: =+IF(TYPE(GEOMEAN($D9:$D27)-1)>1,"",GEOMEAN($D9:$D27)-1) -> 0.019710266 | X9: =+IF(TYPE(GEOMEAN($D9:$D28)-1)>1,"",GEOMEAN($D9:$D28)-1) -> 0.018439692 | Y9: =+IF(TYPE(GEOMEAN($D9:$D29)-1)>1,"",GEOMEAN($D9:$D29)-1) -> 0.020637068 | Z9: =+IF(TYPE(GEOMEAN($D9:$D30)-1)>1,"",GEOMEAN($D9:$D30)-1) -> 0.022264027
A10: =+A9+1 -> 2002 | B10: 0.041316827 | D10: =1+B10 -> 1.0413168 | E10: =+D10-1 -> 0.041316827 | F10: =+IF(TYPE(GEOMEAN($D10:$D11)-1)>1,"",GEOMEAN($D10:$D11)-1) -> 0.033611538 | G10: =+IF(TYPE(GEOMEAN($D10:$D12)-1)>1,"",GEOMEAN($D10:$D12)-1) -> 0.033176118 | H10: =+IF(TYPE(GEOMEAN($D10:$D13)-1)>1,"",GEOMEAN($D10:$D13)-1) -> 0.034236304 | I10: =+IF(TYPE(GEOMEAN($D10:$D14)-1)>1,"",GEOMEAN($D10:$D14)-1) -> 0.032713879 | J10: =+IF(TYPE(GEOMEAN($D10:$D15)-1)>1,"",GEOMEAN($D10:$D15)-1) -> 0.034295167 | K10: =+IF(TYPE(GEOMEAN($D10:$D16)-1)>1,"",GEOMEAN($D10:$D16)-1) -> 0.031419268 | L10: =+IF(TYPE(GEOMEAN($D10:$D17)-1)>1,"",GEOMEAN($D10:$D17)-1) -> 0.028446407 | M10: =+IF(TYPE(GEOMEAN($D10:$D18)-1)>1,"",GEOMEAN($D10:$D18)-1) -> 0.028605015 | N10: =+IF(TYPE(GEOMEAN($D10:$D19)-1)>1,"",GEOMEAN($D10:$D19)-1) -> 0.028119921 | O10: =+IF(TYPE(GEOMEAN($D10:$D20)-1)>1,"",GEOMEAN($D10:$D20)-1) -> 0.028169165 | P10: =+IF(TYPE(GEOMEAN($D10:$D21)-1)>1,"",GEOMEAN($D10:$D21)-1) -> 0.02600883 | Q10: =+IF(TYPE(GEOMEAN($D10:$D22)-1)>1,"",GEOMEAN($D10:$D22)-1) -> 0.023164699 | R10: =+IF(TYPE(GEOMEAN($D10:$D23)-1)>1,"",GEOMEAN($D10:$D23)-1) -> 0.021500218 | S10: =+IF(TYPE(GEOMEAN($D10:$D24)-1)>1,"",GEOMEAN($D10:$D24)-1) -> 0.021112178 | T10: =+IF(TYPE(GEOMEAN($D10:$D25)-1)>1,"",GEOMEAN($D10:$D25)-1) -> 0.020486213 | U10: =+IF(TYPE(GEOMEAN($D10:$D26)-1)>1,"",GEOMEAN($D10:$D26)-1) -> 0.019976257 | V10: =+IF(TYPE(GEOMEAN($D10:$D27)-1)>1,"",GEOMEAN($D10:$D27)-1) -> 0.019302205 | W10: =+IF(TYPE(GEOMEAN($D10:$D28)-1)>1,"",GEOMEAN($D10:$D28)-1) -> 0.017986782 | X10: =+IF(TYPE(GEOMEAN($D10:$D29)-1)>1,"",GEOMEAN($D10:$D29)-1) -> 0.020315817 | Y10: =+IF(TYPE(GEOMEAN($D10:$D30)-1)>1,"",GEOMEAN($D10:$D30)-1) -> 0.0220351 | Z10: =+IF(TYPE(GEOMEAN($D10:$D31)-1)>1,"",GEOMEAN($D10:$D31)-1) -> 0.02244217
A11: =+A10+1 -> 2003 | B11: 0.025963265 | D11: =1+B11 -> 1.0259633 | E11: =+D11-1 -> 0.025963265 | F11: =+IF(TYPE(GEOMEAN($D11:$D12)-1)>1,"",GEOMEAN($D11:$D12)-1) -> 0.02912966 | G11: =+IF(TYPE(GEOMEAN($D11:$D13)-1)>1,"",GEOMEAN($D11:$D13)-1) -> 0.031886844 | H11: =+IF(TYPE(GEOMEAN($D11:$D14)-1)>1,"",GEOMEAN($D11:$D14)-1) -> 0.03057427 | I11: =+IF(TYPE(GEOMEAN($D11:$D15)-1)>1,"",GEOMEAN($D11:$D15)-1) -> 0.032896527 | J11: =+IF(TYPE(GEOMEAN($D11:$D16)-1)>1,"",GEOMEAN($D11:$D16)-1) -> 0.029778845 | K11: =+IF(TYPE(GEOMEAN($D11:$D17)-1)>1,"",GEOMEAN($D11:$D17)-1) -> 0.026620808 | L11: =+IF(TYPE(GEOMEAN($D11:$D18)-1)>1,"",GEOMEAN($D11:$D18)-1) -> 0.027026988 | M11: =+IF(TYPE(GEOMEAN($D11:$D19)-1)>1,"",GEOMEAN($D11:$D19)-1) -> 0.026663962 | N11: =+IF(TYPE(GEOMEAN($D11:$D20)-1)>1,"",GEOMEAN($D11:$D20)-1) -> 0.026863563 | O11: =+IF(TYPE(GEOMEAN($D11:$D21)-1)>1,"",GEOMEAN($D11:$D21)-1) -> 0.024628402 | P11: =+IF(TYPE(GEOMEAN($D11:$D22)-1)>1,"",GEOMEAN($D11:$D22)-1) -> 0.021666381 | Q11: =+IF(TYPE(GEOMEAN($D11:$D23)-1)>1,"",GEOMEAN($D11:$D23)-1) -> 0.019991576 | R11: =+IF(TYPE(GEOMEAN($D11:$D24)-1)>1,"",GEOMEAN($D11:$D24)-1) -> 0.019684081 | S11: =+IF(TYPE(GEOMEAN($D11:$D25)-1)>1,"",GEOMEAN($D11:$D25)-1) -> 0.019112414 | T11: =+IF(TYPE(GEOMEAN($D11:$D26)-1)>1,"",GEOMEAN($D11:$D26)-1) -> 0.018657087 | U11: =+IF(TYPE(GEOMEAN($D11:$D27)-1)>1,"",GEOMEAN($D11:$D27)-1) -> 0.018021818 | V11: =+IF(TYPE(GEOMEAN($D11:$D28)-1)>1,"",GEOMEAN($D11:$D28)-1) -> 0.016706104 | W11: =+IF(TYPE(GEOMEAN($D11:$D29)-1)>1,"",GEOMEAN($D11:$D29)-1) -> 0.019222309 | X11: =+IF(TYPE(GEOMEAN($D11:$D30)-1)>1,"",GEOMEAN($D11:$D30)-1) -> 0.021080441 | Y11: =+IF(TYPE(GEOMEAN($D11:$D31)-1)>1,"",GEOMEAN($D11:$D31)-1) -> 0.02155196 | Z11: =+IF(TYPE(GEOMEAN($D11:$D32)-1)>1,"",GEOMEAN($D11:$D32)-1) -> 0.021863039
A12: =+A11+1 -> 2004 | B12: 0.032305829 | D12: =1+B12 -> 1.0323058 | E12: =+D12-1 -> 0.032305829 | F12: =+IF(TYPE(GEOMEAN($D12:$D13)-1)>1,"",GEOMEAN($D12:$D13)-1) -> 0.034861447 | G12: =+IF(TYPE(GEOMEAN($D12:$D14)-1)>1,"",GEOMEAN($D12:$D14)-1) -> 0.032115872 | H12: =+IF(TYPE(GEOMEAN($D12:$D15)-1)>1,"",GEOMEAN($D12:$D15)-1) -> 0.034637151 | I12: =+IF(TYPE(GEOMEAN($D12:$D16)-1)>1,"",GEOMEAN($D12:$D16)-1) -> 0.030543662 | J12: =+IF(TYPE(GEOMEAN($D12:$D17)-1)>1,"",GEOMEAN($D12:$D17)-1) -> 0.026730439 | K12: =+IF(TYPE(GEOMEAN($D12:$D18)-1)>1,"",GEOMEAN($D12:$D18)-1) -> 0.027179039 | L12: =+IF(TYPE(GEOMEAN($D12:$D19)-1)>1,"",GEOMEAN($D12:$D19)-1) -> 0.026751582 | M12: =+IF(TYPE(GEOMEAN($D12:$D20)-1)>1,"",GEOMEAN($D12:$D20)-1) -> 0.026963645 | N12: =+IF(TYPE(GEOMEAN($D12:$D21)-1)>1,"",GEOMEAN($D12:$D21)-1) -> 0.024495012 | O12: =+IF(TYPE(GEOMEAN($D12:$D22)-1)>1,"",GEOMEAN($D12:$D22)-1) -> 0.021276649 | P12: =+IF(TYPE(GEOMEAN($D12:$D23)-1)>1,"",GEOMEAN($D12:$D23)-1) -> 0.019495507 | Q12: =+IF(TYPE(GEOMEAN($D12:$D24)-1)>1,"",GEOMEAN($D12:$D24)-1) -> 0.019202662 | R12: =+IF(TYPE(GEOMEAN($D12:$D25)-1)>1,"",GEOMEAN($D12:$D25)-1) -> 0.018624822 | S12: =+IF(TYPE(GEOMEAN($D12:$D26)-1)>1,"",GEOMEAN($D12:$D26)-1) -> 0.018171862 | T12: =+IF(TYPE(GEOMEAN($D12:$D27)-1)>1,"",GEOMEAN($D12:$D27)-1) -> 0.017527524 | U12: =+IF(TYPE(GEOMEAN($D12:$D28)-1)>1,"",GEOMEAN($D12:$D28)-1) -> 0.016164174 | V12: =+IF(TYPE(GEOMEAN($D12:$D29)-1)>1,"",GEOMEAN($D12:$D29)-1) -> 0.018849112 | W12: =+IF(TYPE(GEOMEAN($D12:$D30)-1)>1,"",GEOMEAN($D12:$D30)-1) -> 0.020824095 | X12: =+IF(TYPE(GEOMEAN($D12:$D31)-1)>1,"",GEOMEAN($D12:$D31)-1) -> 0.021331894 | Y12: =+IF(TYPE(GEOMEAN($D12:$D32)-1)>1,"",GEOMEAN($D12:$D32)-1) -> 0.021668199 | Z12: =+IF(TYPE(GEOMEAN($D12:$D33)-1)>1,"",GEOMEAN($D12:$D33)-1) -> 0.022060884
A13: =+A12+1 -> 2005 | B13: 0.037423393 | D13: =1+B13 -> 1.0374234 | E13: =+D13-1 -> 0.037423393 | F13: =+IF(TYPE(GEOMEAN($D13:$D14)-1)>1,"",GEOMEAN($D13:$D14)-1) -> 0.032020907 | G13: =+IF(TYPE(GEOMEAN($D13:$D15)-1)>1,"",GEOMEAN($D13:$D15)-1) -> 0.035415428 | H13: =+IF(TYPE(GEOMEAN($D13:$D16)-1)>1,"",GEOMEAN($D13:$D16)-1) -> 0.030103591 | I13: =+IF(TYPE(GEOMEAN($D13:$D17)-1)>1,"",GEOMEAN($D13:$D17)-1) -> 0.02561898 | J13: =+IF(TYPE(GEOMEAN($D13:$D18)-1)>1,"",GEOMEAN($D13:$D18)-1) -> 0.026327053 | K13: =+IF(TYPE(GEOMEAN($D13:$D19)-1)>1,"",GEOMEAN($D13:$D19)-1) -> 0.025960562 | L13: =+IF(TYPE(GEOMEAN($D13:$D20)-1)>1,"",GEOMEAN($D13:$D20)-1) -> 0.026297819 | M13: =+IF(TYPE(GEOMEAN($D13:$D21)-1)>1,"",GEOMEAN($D13:$D21)-1) -> 0.0236308 | N13: =+IF(TYPE(GEOMEAN($D13:$D22)-1)>1,"",GEOMEAN($D13:$D22)-1) -> 0.020180233 | O13: =+IF(TYPE(GEOMEAN($D13:$D23)-1)>1,"",GEOMEAN($D13:$D23)-1) -> 0.018338845 | P13: =+IF(TYPE(GEOMEAN($D13:$D24)-1)>1,"",GEOMEAN($D13:$D24)-1) -> 0.018118268 | Q13: =+IF(TYPE(GEOMEAN($D13:$D25)-1)>1,"",GEOMEAN($D13:$D25)-1) -> 0.017579977 | R13: =+IF(TYPE(GEOMEAN($D13:$D26)-1)>1,"",GEOMEAN($D13:$D26)-1) -> 0.01716973 | S13: =+IF(TYPE(GEOMEAN($D13:$D27)-1)>1,"",GEOMEAN($D13:$D27)-1) -> 0.016549859 | T13: =+IF(TYPE(GEOMEAN($D13:$D28)-1)>1,"",GEOMEAN($D13:$D28)-1) -> 0.015163742 | U13: =+IF(TYPE(GEOMEAN($D13:$D29)-1)>1,"",GEOMEAN($D13:$D29)-1) -> 0.018063026 | V13: =+IF(TYPE(GEOMEAN($D13:$D30)-1)>1,"",GEOMEAN($D13:$D30)-1) -> 0.020189978 | W13: =+IF(TYPE(GEOMEAN($D13:$D31)-1)>1,"",GEOMEAN($D13:$D31)-1) -> 0.020757561 | X13: =+IF(TYPE(GEOMEAN($D13:$D32)-1)>1,"",GEOMEAN($D13:$D32)-1) -> 0.021139205 | Y13: =+IF(TYPE(GEOMEAN($D13:$D33)-1)>1,"",GEOMEAN($D13:$D33)-1) -> 0.021575573 | Z13: =+IF(TYPE(GEOMEAN($D13:$D34)-1)>1,"",GEOMEAN($D13:$D34)-1)
A14: =+A13+1 -> 2006 | B14: 0.026646556 | D14: =1+B14 -> 1.0266466 | E14: =+D14-1 -> 0.026646556 | F14: =+IF(TYPE(GEOMEAN($D14:$D15)-1)>1,"",GEOMEAN($D14:$D15)-1) -> 0.034412904 | G14: =+IF(TYPE(GEOMEAN($D14:$D16)-1)>1,"",GEOMEAN($D14:$D16)-1) -> 0.027675152 | H14: =+IF(TYPE(GEOMEAN($D14:$D17)-1)>1,"",GEOMEAN($D14:$D17)-1) -> 0.022688924 | I14: =+IF(TYPE(GEOMEAN($D14:$D18)-1)>1,"",GEOMEAN($D14:$D18)-1) -> 0.024122068 | J14: =+IF(TYPE(GEOMEAN($D14:$D19)-1)>1,"",GEOMEAN($D14:$D19)-1) -> 0.024062442 | K14: =+IF(TYPE(GEOMEAN($D14:$D20)-1)>1,"",GEOMEAN($D14:$D20)-1) -> 0.024718221 | L14: =+IF(TYPE(GEOMEAN($D14:$D21)-1)>1,"",GEOMEAN($D14:$D21)-1) -> 0.021919669 | M14: =+IF(TYPE(GEOMEAN($D14:$D22)-1)>1,"",GEOMEAN($D14:$D22)-1) -> 0.018282106 | N14: =+IF(TYPE(GEOMEAN($D14:$D23)-1)>1,"",GEOMEAN($D14:$D23)-1) -> 0.016449807 | O14: =+IF(TYPE(GEOMEAN($D14:$D24)-1)>1,"",GEOMEAN($D14:$D24)-1) -> 0.016381171 | P14: =+IF(TYPE(GEOMEAN($D14:$D25)-1)>1,"",GEOMEAN($D14:$D25)-1) -> 0.015943593 | Q14: =+IF(TYPE(GEOMEAN($D14:$D26)-1)>1,"",GEOMEAN($D14:$D26)-1) -> 0.015628233 | R14: =+IF(TYPE(GEOMEAN($D14:$D27)-1)>1,"",GEOMEAN($D14:$D27)-1) -> 0.015075065 | S14: =+IF(TYPE(GEOMEAN($D14:$D28)-1)>1,"",GEOMEAN($D14:$D28)-1) -> 0.013696862 | T14: =+IF(TYPE(GEOMEAN($D14:$D29)-1)>1,"",GEOMEAN($D14:$D29)-1) -> 0.01686507 | U14: =+IF(TYPE(GEOMEAN($D14:$D30)-1)>1,"",GEOMEAN($D14:$D30)-1) -> 0.01918521 | V14: =+IF(TYPE(GEOMEAN($D14:$D31)-1)>1,"",GEOMEAN($D14:$D31)-1) -> 0.019839571 | W14: =+IF(TYPE(GEOMEAN($D14:$D32)-1)>1,"",GEOMEAN($D14:$D32)-1) -> 0.020289258 | X14: =+IF(TYPE(GEOMEAN($D14:$D33)-1)>1,"",GEOMEAN($D14:$D33)-1) -> 0.020789568 | Y14: =+IF(TYPE(GEOMEAN($D14:$D34)-1)>1,"",GEOMEAN($D14:$D34)-1) | Z14: =+IF(TYPE(GEOMEAN($D14:$D35)-1)>1,"",GEOMEAN($D14:$D35)-1)
A15: =+A14+1 -> 2007 | B15: 0.042238002 | D15: =1+B15 -> 1.042238 | E15: =+D15-1 -> 0.042238002 | F15: =+IF(TYPE(GEOMEAN($D15:$D16)-1)>1,"",GEOMEAN($D15:$D16)-1) -> 0.028189836 | G15: =+IF(TYPE(GEOMEAN($D15:$D17)-1)>1,"",GEOMEAN($D15:$D17)-1) -> 0.021373106 | H15: =+IF(TYPE(GEOMEAN($D15:$D18)-1)>1,"",GEOMEAN($D15:$D18)-1) -> 0.023491916 | I15: =+IF(TYPE(GEOMEAN($D15:$D19)-1)>1,"",GEOMEAN($D15:$D19)-1) -> 0.0235464 | J15: =+IF(TYPE(GEOMEAN($D15:$D20)-1)>1,"",GEOMEAN($D15:$D20)-1) -> 0.024397185 | K15: =+IF(TYPE(GEOMEAN($D15:$D21)-1)>1,"",GEOMEAN($D15:$D21)-1) -> 0.021246179 | L15: =+IF(TYPE(GEOMEAN($D15:$D22)-1)>1,"",GEOMEAN($D15:$D22)-1) -> 0.017241352 | M15: =+IF(TYPE(GEOMEAN($D15:$D23)-1)>1,"",GEOMEAN($D15:$D23)-1) -> 0.015323105 | N15: =+IF(TYPE(GEOMEAN($D15:$D24)-1)>1,"",GEOMEAN($D15:$D24)-1) -> 0.015360295 | O15: =+IF(TYPE(GEOMEAN($D15:$D25)-1)>1,"",GEOMEAN($D15:$D25)-1) -> 0.014976147 | P15: =+IF(TYPE(GEOMEAN($D15:$D26)-1)>1,"",GEOMEAN($D15:$D26)-1) -> 0.014715395 | Q15: =+IF(TYPE(GEOMEAN($D15:$D27)-1)>1,"",GEOMEAN($D15:$D27)-1) -> 0.014190371 | R15: =+IF(TYPE(GEOMEAN($D15:$D28)-1)>1,"",GEOMEAN($D15:$D28)-1) -> 0.012778159 | S15: =+IF(TYPE(GEOMEAN($D15:$D29)-1)>1,"",GEOMEAN($D15:$D29)-1) -> 0.016216295 | T15: =+IF(TYPE(GEOMEAN($D15:$D30)-1)>1,"",GEOMEAN($D15:$D30)-1) -> 0.018720681 | U15: =+IF(TYPE(GEOMEAN($D15:$D31)-1)>1,"",GEOMEAN($D15:$D31)-1) -> 0.019440569 | V15: =+IF(TYPE(GEOMEAN($D15:$D32)-1)>1,"",GEOMEAN($D15:$D32)-1) -> 0.019937231 | W15: =+IF(TYPE(GEOMEAN($D15:$D33)-1)>1,"",GEOMEAN($D15:$D33)-1) -> 0.020482233 | X15: =+IF(TYPE(GEOMEAN($D15:$D34)-1)>1,"",GEOMEAN($D15:$D34)-1) | Y15: =+IF(TYPE(GEOMEAN($D15:$D35)-1)>1,"",GEOMEAN($D15:$D35)-1) | Z15: =+IF(TYPE(GEOMEAN($D15:$D36)-1)>1,"",GEOMEAN($D15:$D36)-1)
A16: =+A15+1 -> 2008 | B16: 0.014331023 | D16: =1+B16 -> 1.014331 | E16: =+D16-1 -> 0.014331023 | F16: =+IF(TYPE(GEOMEAN($D16:$D17)-1)>1,"",GEOMEAN($D16:$D17)-1) -> 0.011097822 | G16: =+IF(TYPE(GEOMEAN($D16:$D18)-1)>1,"",GEOMEAN($D16:$D18)-1) -> 0.01731845 | H16: =+IF(TYPE(GEOMEAN($D16:$D19)-1)>1,"",GEOMEAN($D16:$D19)-1) -> 0.018926114 | I16: =+IF(TYPE(GEOMEAN($D16:$D20)-1)>1,"",GEOMEAN($D16:$D20)-1) -> 0.020865837 | J16: =+IF(TYPE(GEOMEAN($D16:$D21)-1)>1,"",GEOMEAN($D16:$D21)-1) -> 0.017788879 | K16: =+IF(TYPE(GEOMEAN($D16:$D22)-1)>1,"",GEOMEAN($D16:$D22)-1) -> 0.013719681 | L16: =+IF(TYPE(GEOMEAN($D16:$D23)-1)>1,"",GEOMEAN($D16:$D23)-1) -> 0.012007987 | M16: =+IF(TYPE(GEOMEAN($D16:$D24)-1)>1,"",GEOMEAN($D16:$D24)-1) -> 0.012417001 | N16: =+IF(TYPE(GEOMEAN($D16:$D25)-1)>1,"",GEOMEAN($D16:$D25)-1) -> 0.012289493 | O16: =+IF(TYPE(GEOMEAN($D16:$D26)-1)>1,"",GEOMEAN($D16:$D26)-1) -> 0.012249672 | P16: =+IF(TYPE(GEOMEAN($D16:$D27)-1)>1,"",GEOMEAN($D16:$D27)-1) -> 0.011887423 | Q16: =+IF(TYPE(GEOMEAN($D16:$D28)-1)>1,"",GEOMEAN($D16:$D28)-1) -> 0.010546812 | R16: =+IF(TYPE(GEOMEAN($D16:$D29)-1)>1,"",GEOMEAN($D16:$D29)-1) -> 0.014382656 | S16: =+IF(TYPE(GEOMEAN($D16:$D30)-1)>1,"",GEOMEAN($D16:$D30)-1) -> 0.017171861 | T16: =+IF(TYPE(GEOMEAN($D16:$D31)-1)>1,"",GEOMEAN($D16:$D31)-1) -> 0.018032401 | U16: =+IF(TYPE(GEOMEAN($D16:$D32)-1)>1,"",GEOMEAN($D16:$D32)-1) -> 0.018640382 | V16: =+IF(TYPE(GEOMEAN($D16:$D33)-1)>1,"",GEOMEAN($D16:$D33)-1) -> 0.019286983 | W16: =+IF(TYPE(GEOMEAN($D16:$D34)-1)>1,"",GEOMEAN($D16:$D34)-1) | X16: =+IF(TYPE(GEOMEAN($D16:$D35)-1)>1,"",GEOMEAN($D16:$D35)-1) | Y16: =+IF(TYPE(GEOMEAN($D16:$D36)-1)>1,"",GEOMEAN($D16:$D36)-1) | Z16: =+IF(TYPE(GEOMEAN($D16:$D37)-1)>1,"",GEOMEAN($D16:$D37)-1)
A17: =+A16+1 -> 2009 | B17: 0.0078749276 | D17: =1+B17 -> 1.0078749 | E17: =+D17-1 -> 0.0078749276 | F17: =+IF(TYPE(GEOMEAN($D17:$D18)-1)>1,"",GEOMEAN($D17:$D18)-1) -> 0.018815462 | G17: =+IF(TYPE(GEOMEAN($D17:$D19)-1)>1,"",GEOMEAN($D17:$D19)-1) -> 0.020462432 | H17: =+IF(TYPE(GEOMEAN($D17:$D20)-1)>1,"",GEOMEAN($D17:$D20)-1) -> 0.022506108 | I17: =+IF(TYPE(GEOMEAN($D17:$D21)-1)>1,"",GEOMEAN($D17:$D21)-1) -> 0.018481863 | J17: =+IF(TYPE(GEOMEAN($D17:$D22)-1)>1,"",GEOMEAN($D17:$D22)-1) -> 0.013617827 | K17: =+IF(TYPE(GEOMEAN($D17:$D23)-1)>1,"",GEOMEAN($D17:$D23)-1) -> 0.011676559 | L17: =+IF(TYPE(GEOMEAN($D17:$D24)-1)>1,"",GEOMEAN($D17:$D24)-1) -> 0.012178002 | M17: =+IF(TYPE(GEOMEAN($D17:$D25)-1)>1,"",GEOMEAN($D17:$D25)-1) -> 0.01206291 | N17: =+IF(TYPE(GEOMEAN($D17:$D26)-1)>1,"",GEOMEAN($D17:$D26)-1) -> 0.012041771 | O17: =+IF(TYPE(GEOMEAN($D17:$D27)-1)>1,"",GEOMEAN($D17:$D27)-1) -> 0.011665569 | P17: =+IF(TYPE(GEOMEAN($D17:$D28)-1)>1,"",GEOMEAN($D17:$D28)-1) -> 0.010232099 | Q17: =+IF(TYPE(GEOMEAN($D17:$D29)-1)>1,"",GEOMEAN($D17:$D29)-1) -> 0.014386628 | R17: =+IF(TYPE(GEOMEAN($D17:$D30)-1)>1,"",GEOMEAN($D17:$D30)-1) -> 0.017375082 | S17: =+IF(TYPE(GEOMEAN($D17:$D31)-1)>1,"",GEOMEAN($D17:$D31)-1) -> 0.018279639 | T17: =+IF(TYPE(GEOMEAN($D17:$D32)-1)>1,"",GEOMEAN($D17:$D32)-1) -> 0.018910324 | U17: =+IF(TYPE(GEOMEAN($D17:$D33)-1)>1,"",GEOMEAN($D17:$D33)-1) -> 0.019579263 | V17: =+IF(TYPE(GEOMEAN($D17:$D34)-1)>1,"",GEOMEAN($D17:$D34)-1) | W17: =+IF(TYPE(GEOMEAN($D17:$D35)-1)>1,"",GEOMEAN($D17:$D35)-1) | X17: =+IF(TYPE(GEOMEAN($D17:$D36)-1)>1,"",GEOMEAN($D17:$D36)-1) | Y17: =+IF(TYPE(GEOMEAN($D17:$D37)-1)>1,"",GEOMEAN($D17:$D37)-1) | Z17: =+IF(TYPE(GEOMEAN($D17:$D38)-1)>1,"",GEOMEAN($D17:$D38)-1)
A18: =+A17+1 -> 2010 | B18: 0.029874756 | D18: =1+B18 -> 1.0298748 | E18: =+D18-1 -> 0.029874756 | F18: =+IF(TYPE(GEOMEAN($D18:$D19)-1)>1,"",GEOMEAN($D18:$D19)-1) -> 0.026815015 | G18: =+IF(TYPE(GEOMEAN($D18:$D20)-1)>1,"",GEOMEAN($D18:$D20)-1) -> 0.027430217 | H18: =+IF(TYPE(GEOMEAN($D18:$D21)-1)>1,"",GEOMEAN($D18:$D21)-1) -> 0.021150993 | I18: =+IF(TYPE(GEOMEAN($D18:$D22)-1)>1,"",GEOMEAN($D18:$D22)-1) -> 0.014770327 | J18: =+IF(TYPE(GEOMEAN($D18:$D23)-1)>1,"",GEOMEAN($D18:$D23)-1) -> 0.012311557 | K18: =+IF(TYPE(GEOMEAN($D18:$D24)-1)>1,"",GEOMEAN($D18:$D24)-1) -> 0.012794225 | L18: =+IF(TYPE(GEOMEAN($D18:$D25)-1)>1,"",GEOMEAN($D18:$D25)-1) -> 0.01258763 | M18: =+IF(TYPE(GEOMEAN($D18:$D26)-1)>1,"",GEOMEAN($D18:$D26)-1) -> 0.012505816 | N18: =+IF(TYPE(GEOMEAN($D18:$D27)-1)>1,"",GEOMEAN($D18:$D27)-1) -> 0.012045417 | O18: =+IF(TYPE(GEOMEAN($D18:$D28)-1)>1,"",GEOMEAN($D18:$D28)-1) -> 0.01044666 | P18: =+IF(TYPE(GEOMEAN($D18:$D29)-1)>1,"",GEOMEAN($D18:$D29)-1) -> 0.014931165 | Q18: =+IF(TYPE(GEOMEAN($D18:$D30)-1)>1,"",GEOMEAN($D18:$D30)-1) -> 0.018109561 | R18: =+IF(TYPE(GEOMEAN($D18:$D31)-1)>1,"",GEOMEAN($D18:$D31)-1) -> 0.01902693 | S18: =+IF(TYPE(GEOMEAN($D18:$D32)-1)>1,"",GEOMEAN($D18:$D32)-1) -> 0.019650299 | T18: =+IF(TYPE(GEOMEAN($D18:$D33)-1)>1,"",GEOMEAN($D18:$D33)-1) -> 0.020315281 | U18: =+IF(TYPE(GEOMEAN($D18:$D34)-1)>1,"",GEOMEAN($D18:$D34)-1) | V18: =+IF(TYPE(GEOMEAN($D18:$D35)-1)>1,"",GEOMEAN($D18:$D35)-1) | W18: =+IF(TYPE(GEOMEAN($D18:$D36)-1)>1,"",GEOMEAN($D18:$D36)-1) | X18: =+IF(TYPE(GEOMEAN($D18:$D37)-1)>1,"",GEOMEAN($D18:$D37)-1) | Y18: =+IF(TYPE(GEOMEAN($D18:$D38)-1)>1,"",GEOMEAN($D18:$D38)-1) | Z18: =+IF(TYPE(GEOMEAN($D18:$D39)-1)>1,"",GEOMEAN($D18:$D39)-1)
A19: =+A18+1 -> 2011 | B19: 0.023764365 | D19: =1+B19 -> 1.0237644 | E19: =+D19-1 -> 0.023764365 | F19: =+IF(TYPE(GEOMEAN($D19:$D20)-1)>1,"",GEOMEAN($D19:$D20)-1) -> 0.026210124 | G19: =+IF(TYPE(GEOMEAN($D19:$D21)-1)>1,"",GEOMEAN($D19:$D21)-1) -> 0.018259525 | H19: =+IF(TYPE(GEOMEAN($D19:$D22)-1)>1,"",GEOMEAN($D19:$D22)-1) -> 0.011028961 | I19: =+IF(TYPE(GEOMEAN($D19:$D23)-1)>1,"",GEOMEAN($D19:$D23)-1) -> 0.0088350241 | J19: =+IF(TYPE(GEOMEAN($D19:$D24)-1)>1,"",GEOMEAN($D19:$D24)-1) -> 0.0099751386 | K19: =+IF(TYPE(GEOMEAN($D19:$D25)-1)>1,"",GEOMEAN($D19:$D25)-1) -> 0.010141843 | L19: =+IF(TYPE(GEOMEAN($D19:$D26)-1)>1,"",GEOMEAN($D19:$D26)-1) -> 0.010355397 | M19: =+IF(TYPE(GEOMEAN($D19:$D27)-1)>1,"",GEOMEAN($D19:$D27)-1) -> 0.010083531 | N19: =+IF(TYPE(GEOMEAN($D19:$D28)-1)>1,"",GEOMEAN($D19:$D28)-1) -> 0.0085241236 | O19: =+IF(TYPE(GEOMEAN($D19:$D29)-1)>1,"",GEOMEAN($D19:$D29)-1) -> 0.013583456 | P19: =+IF(TYPE(GEOMEAN($D19:$D30)-1)>1,"",GEOMEAN($D19:$D30)-1) -> 0.017135217 | Q19: =+IF(TYPE(GEOMEAN($D19:$D31)-1)>1,"",GEOMEAN($D19:$D31)-1) -> 0.01819723 | R19: =+IF(TYPE(GEOMEAN($D19:$D32)-1)>1,"",GEOMEAN($D19:$D32)-1) -> 0.018923877 | S19: =+IF(TYPE(GEOMEAN($D19:$D33)-1)>1,"",GEOMEAN($D19:$D33)-1) -> 0.019681147 | T19: =+IF(TYPE(GEOMEAN($D19:$D34)-1)>1,"",GEOMEAN($D19:$D34)-1) | U19: =+IF(TYPE(GEOMEAN($D19:$D35)-1)>1,"",GEOMEAN($D19:$D35)-1) | V19: =+IF(TYPE(GEOMEAN($D19:$D36)-1)>1,"",GEOMEAN($D19:$D36)-1) | W19: =+IF(TYPE(GEOMEAN($D19:$D37)-1)>1,"",GEOMEAN($D19:$D37)-1) | X19: =+IF(TYPE(GEOMEAN($D19:$D38)-1)>1,"",GEOMEAN($D19:$D38)-1) | Y19: =+IF(TYPE(GEOMEAN($D19:$D39)-1)>1,"",GEOMEAN($D19:$D39)-1) | Z19: =+IF(TYPE(GEOMEAN($D19:$D40)-1)>1,"",GEOMEAN($D19:$D40)-1)
... A33: =+A32+1 -> 2025 | B33: 0.030342212 | D33: =1+B33 -> 1.0303422 | E33: =+D33-1 -> 0.030342212 | F33: =+IF(TYPE(GEOMEAN($D33:$D34)-1)>1,"",GEOMEAN($D33:$D34)-1) | G33: =+IF(TYPE(GEOMEAN($D33:$D35)-1)>1,"",GEOMEAN($D33:$D35)-1) | H33: =+IF(TYPE(GEOMEAN($D33:$D36)-1)>1,"",GEOMEAN($D33:$D36)-1) | I33: =+IF(TYPE(GEOMEAN($D33:$D37)-1)>1,"",GEOMEAN($D33:$D37)-1) | J33: =+IF(TYPE(GEOMEAN($D33:$D38)-1)>1,"",GEOMEAN($D33:$D38)-1) | K33: =+IF(TYPE(GEOMEAN($D33:$D39)-1)>1,"",GEOMEAN($D33:$D39)-1) | L33: =+IF(TYPE(GEOMEAN($D33:$D40)-1)>1,"",GEOMEAN($D33:$D40)-1) | M33: =+IF(TYPE(GEOMEAN($D33:$D41)-1)>1,"",GEOMEAN($D33:$D41)-1) | N33: =+IF(TYPE(GEOMEAN($D33:$D42)-1)>1,"",GEOMEAN($D33:$D42)-1) | O33: =+IF(TYPE(GEOMEAN($D33:$D43)-1)>1,"",GEOMEAN($D33:$D43)-1) | P33: =+IF(TYPE(GEOMEAN($D33:$D44)-1)>1,"",GEOMEAN($D33:$D44)-1) | Q33: =+IF(TYPE(GEOMEAN($D33:$D45)-1)>1,"",GEOMEAN($D33:$D45)-1) | R33: =+IF(TYPE(GEOMEAN($D33:$D46)-1)>1,"",GEOMEAN($D33:$D46)-1) | S33: =+IF(TYPE(GEOMEAN($D33:$D47)-1)>1,"",GEOMEAN($D33:$D47)-1) | T33: =+IF(TYPE(GEOMEAN($D33:$D48)-1)>1,"",GEOMEAN($D33:$D48)-1) | U33: =+IF(TYPE(GEOMEAN($D33:$D49)-1)>1,"",GEOMEAN($D33:$D49)-1) | V33: =+IF(TYPE(GEOMEAN($D33:$D50)-1)>1,"",GEOMEAN($D33:$D50)-1) | W33: =+IF(TYPE(GEOMEAN($D33:$D51)-1)>1,"",GEOMEAN($D33:$D51)-1) | X33: =+IF(TYPE(GEOMEAN($D33:$D52)-1)>1,"",GEOMEAN($D33:$D52)-1) | Y33: =+IF(TYPE(GEOMEAN($D33:$D53)-1)>1,"",GEOMEAN($D33:$D53)-1) | Z33: =+IF(TYPE(GEOMEAN($D33:$D54)-1)>1,"",GEOMEAN($D33:$D54)-1)
D34: 0 | P34: =+IF(TYPE(GEOMEAN($D34:$D47)-1)>1,"",GEOMEAN($D34:$D47)-1)
B36: medias aritméticas desde 1999 | E36: =+AVERAGE(E7:E33) -> 0.024153201 | F36: =+AVERAGE(F7:F33) -> 0.023892139 | G36: =+AVERAGE(G7:G33) -> 0.023518793 | H36: =+AVERAGE(H7:H33) -> 0.023199163 | I36: =+AVERAGE(I7:I33) -> 0.022540931 | J36: =+AVERAGE(J7:J33) -> 0.021714474 | K36: =+AVERAGE(K7:K33) -> 0.021185784 | L36: =+AVERAGE(L7:L33) -> 0.020730622 | ... Z36: =+AVERAGE(Z7:Z33) -> 0.021666132
B37: 1+ tanto acumulado | E37: =1+E36 -> 1.0241532 | F37: =+E37*(1+F36) -> 1.0486224 | G37: =+F37*(1+G36) -> 1.0732847 | H37: =+G37*(1+H36) -> 1.0981841 | I37: =+H37*(1+I36) -> 1.1229381 | J37: =+I37*(1+J36) -> 1.1473222 | K37: =+J37*(1+K36) -> 1.1716291 | L37: =+K37*(1+L36) -> 1.1959177 | M37: =+L37*(1+M36) -> 1.2202613 | ... Z37: =+Y37*(1+Z36) -> 1.579244
B38: tanto acumulado | E38: =+E37-1 -> 0.024153201 | F38: =+F37-1 -> 0.048622412 | G38: =+G37-1 -> 0.073284745 | H38: =+H37-1 -> 0.098184053 | I38: =+I37-1 -> 0.12293814 | J38: =+J37-1 -> 0.14732215 | K38: =+K37-1 -> 0.17162907 | L38: =+L37-1 -> 0.19591767 | ... Z38: =+Z37-1 -> 0.57924395

Sheet selec10a
A6: year | B6: =+CONCATENATE("H_",'bono 10a esp'!E6) -> H_1 | C6: =+CONCATENATE("H_",'bono 10a esp'!F6) -> H_2 | D6: =+CONCATENATE("H_",'bono 10a esp'!G6) -> H_3 | E6: =+CONCATENATE("H_",'bono 10a esp'!H6) -> H_4 | F6: =+CONCATENATE("H_",'bono 10a esp'!I6) -> H_5 | G6: =+CONCATENATE("H_",'bono 10a esp'!J6) -> H_6 | H6: =+CONCATENATE("H_",'bono 10a esp'!K6) -> H_7 | I6: =+CONCATENATE("H_",'bono 10a esp'!L6) -> H_8 | ... U6: =+CONCATENATE("H_",'bono 10a esp'!X6) -> H_20
A7: =+'bono 10a esp'!A7 -> 1999 | B7: =+IF('bono 10a esp'!E7="","",(1+'bono 10a esp'!E7)^('bono 10a esp'!E$6)-1) -> 0.0485 | C7: =+IF('bono 10a esp'!F7="","",(1+'bono 10a esp'!F7)^('bono 10a esp'!F$6)-1) -> 0.10962755 | D7: =+IF('bono 10a esp'!G7="","",(1+'bono 10a esp'!G7)^('bono 10a esp'!G$6)-1) -> 0.16755011 | E7: =+IF('bono 10a esp'!H7="","",(1+'bono 10a esp'!H7)^('bono 10a esp'!H$6)-1) -> 0.2280292 | F7: =+IF('bono 10a esp'!I7="","",(1+'bono 10a esp'!I7)^('bono 10a esp'!I$6)-1) -> 0.28120287 | G7: =+IF('bono 10a esp'!J7="","",(1+'bono 10a esp'!J7)^('bono 10a esp'!J$6)-1) -> 0.33629459 | H7: =+IF('bono 10a esp'!K7="","",(1+'bono 10a esp'!K7)^('bono 10a esp'!K$6)-1) -> 0.38814282 | I7: =+IF('bono 10a esp'!L7="","",(1+'bono 10a esp'!L7)^('bono 10a esp'!L$6)-1) -> 0.43436798 | ... U7: =+IF('bono 10a esp'!X7="","",(1+'bono 10a esp'!X7)^('bono 10a esp'!X$6)-1) -> 1.173998
A8: =+'bono 10a esp'!A8 -> 2000 | B8: =+IF('bono 10a esp'!E8="","",(1+'bono 10a esp'!E8)^('bono 10a esp'!E$6)-1) -> 0.0583 | C8: =+IF('bono 10a esp'!F8="","",(1+'bono 10a esp'!F8)^('bono 10a esp'!F$6)-1) -> 0.11354326 | D8: =+IF('bono 10a esp'!G8="","",(1+'bono 10a esp'!G8)^('bono 10a esp'!G$6)-1) -> 0.1712248 | E8: =+IF('bono 10a esp'!H8="","",(1+'bono 10a esp'!H8)^('bono 10a esp'!H$6)-1) -> 0.22193883 | F8: =+IF('bono 10a esp'!I8="","",(1+'bono 10a esp'!I8)^('bono 10a esp'!I$6)-1) -> 0.2744822 | G8: =+IF('bono 10a esp'!J8="","",(1+'bono 10a esp'!J8)^('bono 10a esp'!J$6)-1) -> 0.32393211 | H8: =+IF('bono 10a esp'!K8="","",(1+'bono 10a esp'!K8)^('bono 10a esp'!K$6)-1) -> 0.36801905 | I8: =+IF('bono 10a esp'!L8="","",(1+'bono 10a esp'!L8)^('bono 10a esp'!L$6)-1) -> 0.42273982 | ... U8: =+IF('bono 10a esp'!X8="","",(1+'bono 10a esp'!X8)^('bono 10a esp'!X$6)-1) -> 1.0805503
A9: =+'bono 10a esp'!A9 -> 2001 | B9: =+IF('bono 10a esp'!E9="","",(1+'bono 10a esp'!E9)^('bono 10a esp'!E$6)-1) -> 0.0522 | C9: =+IF('bono 10a esp'!F9="","",(1+'bono 10a esp'!F9)^('bono 10a esp'!F$6)-1) -> 0.10670396 | D9: =+IF('bono 10a esp'!G9="","",(1+'bono 10a esp'!G9)^('bono 10a esp'!G$6)-1) -> 0.15462424 | E9: =+IF('bono 10a esp'!H9="","",(1+'bono 10a esp'!H9)^('bono 10a esp'!H$6)-1) -> 0.20427308 | F9: =+IF('bono 10a esp'!I9="","",(1+'bono 10a esp'!I9)^('bono 10a esp'!I$6)-1) -> 0.25099888 | G9: =+IF('bono 10a esp'!J9="","",(1+'bono 10a esp'!J9)^('bono 10a esp'!J$6)-1) -> 0.29265714 | H9: =+IF('bono 10a esp'!K9="","",(1+'bono 10a esp'!K9)^('bono 10a esp'!K$6)-1) -> 0.34436343 | I9: =+IF('bono 10a esp'!L9="","",(1+'bono 10a esp'!L9)^('bono 10a esp'!L$6)-1) -> 0.40351542 | ... U9: =+IF('bono 10a esp'!X9="","",(1+'bono 10a esp'!X9)^('bono 10a esp'!X$6)-1) -> 0.97340675
A10: =+'bono 10a esp'!A10 -> 2002 | B10: =+IF('bono 10a esp'!E10="","",(1+'bono 10a esp'!E10)^('bono 10a esp'!E$6)-1) -> 0.0518 | C10: =+IF('bono 10a esp'!F10="","",(1+'bono 10a esp'!F10)^('bono 10a esp'!F$6)-1) -> 0.09734294 | D10: =+IF('bono 10a esp'!G10="","",(1+'bono 10a esp'!G10)^('bono 10a esp'!G$6)-1) -> 0.14452869 | E10: =+IF('bono 10a esp'!H10="","",(1+'bono 10a esp'!H10)^('bono 10a esp'!H$6)-1) -> 0.1889364 | F10: =+IF('bono 10a esp'!I10="","",(1+'bono 10a esp'!I10)^('bono 10a esp'!I$6)-1) -> 0.22852798 | G10: =+IF('bono 10a esp'!J10="","",(1+'bono 10a esp'!J10)^('bono 10a esp'!J$6)-1) -> 0.2776691 | H10: =+IF('bono 10a esp'!K10="","",(1+'bono 10a esp'!K10)^('bono 10a esp'!K$6)-1) -> 0.33388654 | I10: =+IF('bono 10a esp'!L10="","",(1+'bono 10a esp'!L10)^('bono 10a esp'!L$6)-1) -> 0.38670845 | ... U10: =+IF('bono 10a esp'!X10="","",(1+'bono 10a esp'!X10)^('bono 10a esp'!X$6)-1) -> 0.88206964
A11: =+'bono 10a esp'!A11 -> 2003 | B11: =+IF('bono 10a esp'!E11="","",(1+'bono 10a esp'!E11)^('bono 10a esp'!E$6)-1) -> 0.0433 | C11: =+IF('bono 10a esp'!F11="","",(1+'bono 10a esp'!F11)^('bono 10a esp'!F$6)-1) -> 0.0881619 | D11: =+IF('bono 10a esp'!G11="","",(1+'bono 10a esp'!G11)^('bono 10a esp'!G$6)-1) -> 0.13038258 | E11: =+IF('bono 10a esp'!H11="","",(1+'bono 10a esp'!H11)^('bono 10a esp'!H$6)-1) -> 0.16802432 | F11: =+IF('bono 10a esp'!I11="","",(1+'bono 10a esp'!I11)^('bono 10a esp'!I$6)-1) -> 0.21474529 | G11: =+IF('bono 10a esp'!J11="","",(1+'bono 10a esp'!J11)^('bono 10a esp'!J$6)-1) -> 0.26819409 | H11: =+IF('bono 10a esp'!K11="","",(1+'bono 10a esp'!K11)^('bono 10a esp'!K$6)-1) -> 0.31841457 | I11: =+IF('bono 10a esp'!L11="","",(1+'bono 10a esp'!L11)^('bono 10a esp'!L$6)-1) -> 0.36983274 | ... U11: =+IF('bono 10a esp'!X11="","",(1+'bono 10a esp'!X11)^('bono 10a esp'!X$6)-1) -> 0.82874612
A12: =+'bono 10a esp'!A12 -> 2004 | B12: =+IF('bono 10a esp'!E12="","",(1+'bono 10a esp'!E12)^('bono 10a esp'!E$6)-1) -> 0.043 | C12: =+IF('bono 10a esp'!F12="","",(1+'bono 10a esp'!F12)^('bono 10a esp'!F$6)-1) -> 0.0834684 | D12: =+IF('bono 10a esp'!G12="","",(1+'bono 10a esp'!G12)^('bono 10a esp'!G$6)-1) -> 0.1195479 | E12: =+IF('bono 10a esp'!H12="","",(1+'bono 10a esp'!H12)^('bono 10a esp'!H$6)-1) -> 0.16432981 | F12: =+IF('bono 10a esp'!I12="","",(1+'bono 10a esp'!I12)^('bono 10a esp'!I$6)-1) -> 0.21556033 | G12: =+IF('bono 10a esp'!J12="","",(1+'bono 10a esp'!J12)^('bono 10a esp'!J$6)-1) -> 0.26369651 | H12: =+IF('bono 10a esp'!K12="","",(1+'bono 10a esp'!K12)^('bono 10a esp'!K$6)-1) -> 0.31298068 | I12: =+IF('bono 10a esp'!L12="","",(1+'bono 10a esp'!L12)^('bono 10a esp'!L$6)-1) -> 0.38453813 | ... U12: =+IF('bono 10a esp'!X12="","",(1+'bono 10a esp'!X12)^('bono 10a esp'!X$6)-1) -> 0.8140222
A13: =+'bono 10a esp'!A13 -> 2005 | B13: =+IF('bono 10a esp'!E13="","",(1+'bono 10a esp'!E13)^('bono 10a esp'!E$6)-1) -> 0.0388 | C13: =+IF('bono 10a esp'!F13="","",(1+'bono 10a esp'!F13)^('bono 10a esp'!F$6)-1) -> 0.07339204 | D13: =+IF('bono 10a esp'!G13="","",(1+'bono 10a esp'!G13)^('bono 10a esp'!G$6)-1) -> 0.11632772 | E13: =+IF('bono 10a esp'!H13="","",(1+'bono 10a esp'!H13)^('bono 10a esp'!H$6)-1) -> 0.16544614 | F13: =+IF('bono 10a esp'!I13="","",(1+'bono 10a esp'!I13)^('bono 10a esp'!I$6)-1) -> 0.21159781 | G13: =+IF('bono 10a esp'!J13="","",(1+'bono 10a esp'!J13)^('bono 10a esp'!J$6)-1) -> 0.25885012 | H13: =+IF('bono 10a esp'!K13="","",(1+'bono 10a esp'!K13)^('bono 10a esp'!K$6)-1) -> 0.32745745 | I13: =+IF('bono 10a esp'!L13="","",(1+'bono 10a esp'!L13)^('bono 10a esp'!L$6)-1) -> 0.39409582 | ... U13: =+IF('bono 10a esp'!X13="","",(1+'bono 10a esp'!X13)^('bono 10a esp'!X$6)-1) -> 0.79402099
A14: =+'bono 10a esp'!A14 -> 2006 | B14: =+IF('bono 10a esp'!E14="","",(1+'bono 10a esp'!E14)^('bono 10a esp'!E$6)-1) -> 0.0333 | C14: =+IF('bono 10a esp'!F14="","",(1+'bono 10a esp'!F14)^('bono 10a esp'!F$6)-1) -> 0.074632 | D14: =+IF('bono 10a esp'!G14="","",(1+'bono 10a esp'!G14)^('bono 10a esp'!G$6)-1) -> 0.12191581 | E14: =+IF('bono 10a esp'!H14="","",(1+'bono 10a esp'!H14)^('bono 10a esp'!H$6)-1) -> 0.16634367 | F14: =+IF('bono 10a esp'!I14="","",(1+'bono 10a esp'!I14)^('bono 10a esp'!I$6)-1) -> 0.21183108 | G14: =+IF('bono 10a esp'!J14="","",(1+'bono 10a esp'!J14)^('bono 10a esp'!J$6)-1) -> 0.27787587 | H14: =+IF('bono 10a esp'!K14="","",(1+'bono 10a esp'!K14)^('bono 10a esp'!K$6)-1) -> 0.34202524 | I14: =+IF('bono 10a esp'!L14="","",(1+'bono 10a esp'!L14)^('bono 10a esp'!L$6)-1) -> 0.41664184 | ... U14: =+IF('bono 10a esp'!X14="","",(1+'bono 10a esp'!X14)^('bono 10a esp'!X$6)-1) -> 0.78262271
A15: =+'bono 10a esp'!A15 -> 2007 | B15: =+IF('bono 10a esp'!E15="","",(1+'bono 10a esp'!E15)^('bono 10a esp'!E$6)-1) -> 0.04 | C15: =+IF('bono 10a esp'!F15="","",(1+'bono 10a esp'!F15)^('bono 10a esp'!F$6)-1) -> 0.08576 | D15: =+IF('bono 10a esp'!G15="","",(1+'bono 10a esp'!G15)^('bono 10a esp'!G$6)-1) -> 0.1287561 | E15: =+IF('bono 10a esp'!H15="","",(1+'bono 10a esp'!H15)^('bono 10a esp'!H$6)-1) -> 0.17277758 | F15: =+IF('bono 10a esp'!I15="","",(1+'bono 10a esp'!I15)^('bono 10a esp'!I$6)-1) -> 0.23669396 | G15: =+IF('bono 10a esp'!J15="","",(1+'bono 10a esp'!J15)^('bono 10a esp'!J$6)-1) -> 0.298776 | H15: =+IF('bono 10a esp'!K15="","",(1+'bono 10a esp'!K15)^('bono 10a esp'!K$6)-1) -> 0.37098794 | I15: =+IF('bono 10a esp'!L15="","",(1+'bono 10a esp'!L15)^('bono 10a esp'!L$6)-1) -> 0.42760975 | ... U15: =+IF('bono 10a esp'!X15="","",(1+'bono 10a esp'!X15)^('bono 10a esp'!X$6)-1)
